<sdf version='1.6'>
  <world name='default'>
    <light name='sun' type='directional'>
      <cast_shadows>1</cast_shadows>
      <pose frame=''>0 0 10 0 -0 0</pose>
      <diffuse>0.8 0.8 0.8 1</diffuse>
      <specular>0.2 0.2 0.2 1</specular>
      <attenuation>
        <range>1000</range>
        <constant>0.9</constant>
        <linear>0.01</linear>
        <quadratic>0.001</quadratic>
      </attenuation>
      <direction>-0.5 0.1 -0.9</direction>
    </light>
    <model name='ground_plane'>
      <static>1</static>
      <link name='link'>
        <collision name='collision'>
          <geometry>
            <plane>
              <normal>0 0 1</normal>
              <size>1000 1000</size>
            </plane>
          </geometry>
          <surface>
            <contact>
              <collide_bitmask>65535</collide_bitmask>
              <ode/>
            </contact>
            <friction>
              <ode>
                <mu>100</mu>
                <mu2>50</mu2>
              </ode>
              <torsional>
                <ode/>
              </torsional>
            </friction>
            <bounce/>
          </surface>
          <max_contacts>10</max_contacts>
        </collision>
        <visual name='visual'>
          <cast_shadows>0</cast_shadows>
          <geometry>
            <plane>
              <normal>0 0 1</normal>
              <size>1000 1000</size>
            </plane>
          </geometry>
          <material>
            <script>
              <uri>file://media/materials/scripts/gazebo.material</uri>
              <name>Gazebo/Grass</name>
            </script>
          </material>
        </visual>
        <self_collide>0</self_collide>
        <enable_wind>0</enable_wind>
        <kinematic>0</kinematic>
      </link>
    </model>
    <gravity>0 0 -9.8</gravity>
    <magnetic_field>6e-06 2.3e-05 -4.2e-05</magnetic_field>
    <atmosphere type='adiabatic'/>
    <physics name='default_physics' default='0' type='ode'>
      <max_step_size>0.001</max_step_size>
      <real_time_factor>1</real_time_factor>
      <real_time_update_rate>1000</real_time_update_rate>
    </physics>
    <scene>
      <ambient>0.4 0.4 0.4 1</ambient>
      <background>0.7 0.7 0.7 1</background>
      <sky>
        <time>18</time>
      </sky>
      <shadows>0</shadows>
    </scene>
    <audio>
      <device>default</device>
    </audio>
    <wind/>
    <spherical_coordinates>
      <surface_model>EARTH_WGS84</surface_model>
      <latitude_deg>0</latitude_deg>
      <longitude_deg>0</longitude_deg>
      <elevation>0</elevation>
      <heading_deg>0</heading_deg>
    </spherical_coordinates>
    <state world_name='default'>
      <sim_time>39890 639000000</sim_time>
      <real_time>41 184897133</real_time>
      <wall_time>1593861936 886721165</wall_time>
      <iterations>9815</iterations>
      <model name='(DS) Curved Road - 100m'>
        <pose frame=''>-52.4991 -103.932 0 0 0 -1.5708</pose>
        <scale>1 1 1</scale>
        <link name='link'>
          <pose frame=''>-52.4991 -103.932 0 0 0 -1.5708</pose>
          <velocity>0 0 0 0 -0 0</velocity>
          <acceleration>0 0 0 0 -0 0</acceleration>
          <wrench>0 0 0 0 -0 0</wrench>
        </link>
      </model>
      <model name='(DS) Curved Road - 100m_0'>
        <pose frame=''>52.9334 -103.946 0 0 0 -4e-06</pose>
        <scale>1 1 1</scale>
        <link name='link'>
          <pose frame=''>52.9334 -103.946 0 0 0 -4e-06</pose>
          <velocity>0 0 0 0 -0 0</velocity>
          <acceleration>0 0 0 0 -0 0</acceleration>
          <wrench>0 0 0 0 -0 0</wrench>
        </link>
      </model>
      <model name='(DS) Curved Road - 100m_1'>
        <pose frame=''>-52.5041 101.39 0 0 -0 3.14159</pose>
        <scale>1 1 1</scale>
        <link name='link'>
          <pose frame=''>-52.5041 101.39 0 0 -0 3.14159</pose>
          <velocity>0 0 0 0 -0 0</velocity>
          <acceleration>0 0 0 0 -0 0</acceleration>
          <wrench>0 0 0 0 -0 0</wrench>
        </link>
      </model>
      <model name='(DS) Curved Road - 100m_3'>
        <pose frame=''>52.9263 101.377 0 0 -0 1.5708</pose>
        <scale>1 1 1</scale>
        <link name='link'>
          <pose frame=''>52.9263 101.377 0 0 -0 1.5708</pose>
          <velocity>0 0 0 0 -0 0</velocity>
          <acceleration>0 0 0 0 -0 0</acceleration>
          <wrench>0 0 0 0 -0 0</wrench>
        </link>
      </model>
      <model name='(DS) Curved Road - 50m'>
        <pose frame=''>27.7853 27.8466 0 0 -0 1.5708</pose>
        <scale>1 1 1</scale>
        <link name='link'>
          <pose frame=''>27.7853 27.8466 0 0 -0 1.5708</pose>
          <velocity>0 0 0 0 -0 0</velocity>
          <acceleration>0 0 0 0 -0 0</acceleration>
          <wrench>0 0 0 0 -0 0</wrench>
        </link>
      </model>
      <model name='(DS) Curved Road - 50m_0'>
        <pose frame=''>27.7786 -27.624 0 0 -0 0</pose>
        <scale>1 1 1</scale>
        <link name='link'>
          <pose frame=''>27.7786 -27.624 0 0 -0 0</pose>
          <velocity>0 0 0 0 -0 0</velocity>
          <acceleration>0 0 0 0 -0 0</acceleration>
          <wrench>0 0 0 0 -0 0</wrench>
        </link>
      </model>
      <model name='(DS) Curved Road - 50m_1'>
        <pose frame=''>-27.6718 -27.6117 0 0 0 -1.5708</pose>
        <scale>1 1 1</scale>
        <link name='link'>
          <pose frame=''>-27.6718 -27.6117 0 0 0 -1.5708</pose>
          <velocity>0 0 0 0 -0 0</velocity>
          <acceleration>0 0 0 0 -0 0</acceleration>
          <wrench>0 0 0 0 -0 0</wrench>
        </link>
      </model>
      <model name='(DS) Curved Road - 50m_2'>
        <pose frame=''>-27.6656 27.8286 0 0 0 -3.14159</pose>
        <scale>1 1 1</scale>
        <link name='link'>
          <pose frame=''>-27.6656 27.8286 0 0 0 -3.14159</pose>
          <velocity>0 0 0 0 -0 0</velocity>
          <acceleration>0 0 0 0 -0 0</acceleration>
          <wrench>0 0 0 0 -0 0</wrench>
        </link>
      </model>
      <model name='(DS) Straight Road - 100m'>
        <pose frame=''>110.195 -1.2407 0 0 0 -1.5708</pose>
        <scale>1 1 1</scale>
        <link name='link'>
          <pose frame=''>110.195 -1.2407 0 0 0 -1.5708</pose>
          <velocity>0 0 0 0 -0 0</velocity>
          <acceleration>0 0 0 0 -0 0</acceleration>
          <wrench>0 0 0 0 -0 0</wrench>
        </link>
      </model>
      <model name='(DS) Straight Road - 100m_0'>
        <pose frame=''>-89.6938 -1.22601 0 0 0 -1.5708</pose>
        <scale>1 1 1</scale>
        <link name='link'>
          <pose frame=''>-89.6938 -1.22601 0 0 0 -1.5708</pose>
          <velocity>0 0 0 0 -0 0</velocity>
          <acceleration>0 0 0 0 -0 0</acceleration>
          <wrench>0 0 0 0 -0 0</wrench>
        </link>
      </model>
      <model name='(DS) Straight Road - 50m'>
        <pose frame=''>75.2043 9.99251 0 0 -0 0</pose>
        <scale>1 1 1</scale>
        <link name='link'>
          <pose frame=''>75.2043 9.99251 0 0 -0 0</pose>
          <velocity>0 0 0 0 -0 0</velocity>
          <acceleration>0 0 0 0 -0 0</acceleration>
          <wrench>0 0 0 0 -0 0</wrench>
        </link>
      </model>
      <model name='(DS) Straight Road - 50m_0'>
        <pose frame=''>-75.8954 9.7691 0 0 -0 0</pose>
        <scale>1 1 1</scale>
        <link name='link'>
          <pose frame=''>-75.8954 9.7691 0 0 -0 0</pose>
          <velocity>0 0 0 0 -0 0</velocity>
          <acceleration>0 0 0 0 -0 0</acceleration>
          <wrench>0 0 0 0 -0 0</wrench>
        </link>
      </model>
      <model name='(DS) Straight Road - 50m_1'>
        <pose frame=''>9.99517 80.1181 0 0 0 -1.5708</pose>
        <scale>1 1 1</scale>
        <link name='link'>
          <pose frame=''>9.99517 80.1181 0 0 0 -1.5708</pose>
          <velocity>0 0 0 0 -0 0</velocity>
          <acceleration>0 0 0 0 -0 0</acceleration>
          <wrench>0 0 0 0 -0 0</wrench>
        </link>
      </model>
      <model name='(DS) Straight Road - 50m_2'>
        <pose frame=''>10.0588 -79.5889 0 0 0 -1.5708</pose>
        <scale>1 1 1</scale>
        <link name='link'>
          <pose frame=''>10.0588 -79.5889 0 0 0 -1.5708</pose>
          <velocity>0 0 0 0 -0 0</velocity>
          <acceleration>0 0 0 0 -0 0</acceleration>
          <wrench>0 0 0 0 -0 0</wrench>
        </link>
      </model>
      <model name='Fast Food'>
        <pose frame=''>2.67316 -108.278 0 0 -0 0</pose>
        <scale>1 1 1</scale>
        <link name='link'>
          <pose frame=''>2.67316 -108.278 3.15931 0 -0 0</pose>
          <velocity>0 0 0 0 -0 0</velocity>
          <acceleration>0 0 0 0 -0 0</acceleration>
          <wrench>0 0 0 0 -0 0</wrench>
        </link>
      </model>
      <model name='Gas Station'>
        <pose frame=''>11.2582 102.355 0 0 0 -1.5708</pose>
        <scale>1 1 1</scale>
        <link name='link'>
          <pose frame=''>11.2582 102.355 0 0 -0 -1.5708</pose>
          <velocity>0 0 0 0 -0 0</velocity>
          <acceleration>0 0 0 0 -0 0</acceleration>
          <wrench>0 0 0 0 -0 0</wrench>
        </link>
      </model>
      <model name='Stop Sign'>
        <pose frame=''>94.2217 -5.20314 0 0 0 -1.5708</pose>
        <scale>1 1 1</scale>
        <link name='link'>
          <pose frame=''>94.2217 -5.20314 0 0 0 -1.5708</pose>
          <velocity>0 0 0 0 -0 0</velocity>
          <acceleration>0 0 0 0 -0 0</acceleration>
          <wrench>0 0 0 0 -0 0</wrench>
        </link>
      </model>
      <model name='Stop Sign_0'>
        <pose frame=''>-94.095 4.72945 0 0 -0 1.5708</pose>
        <scale>1 1 1</scale>
        <link name='link'>
          <pose frame=''>-94.095 4.72945 0 0 -0 1.5708</pose>
          <velocity>0 0 0 0 -0 0</velocity>
          <acceleration>0 0 0 0 -0 0</acceleration>
          <wrench>0 0 0 0 -0 0</wrench>
        </link>
      </model>
      <model name='ambulance'>
        <pose frame=''>-43.6618 -17.3946 0.11 0 -0 0.389699</pose>
        <scale>1 1 1</scale>
        <link name='link'>
          <pose frame=''>-43.6618 -17.3946 0.11 0 -0 0.389699</pose>
          <velocity>0 0 0 0 -0 0</velocity>
          <acceleration>0 0 0 0 -0 0</acceleration>
          <wrench>0 0 0 0 -0 0</wrench>
        </link>
      </model>
      <model name='bus'>
        <pose frame=''>43.8108 17.4223 0.11 0 -0 -2.75388</pose>
        <scale>1 1 1</scale>
        <link name='link'>
          <pose frame=''>43.8108 17.4223 0.11 0 -0 -2.75388</pose>
          <velocity>0 0 0 0 -0 0</velocity>
          <acceleration>0 0 0 0 -0 0</acceleration>
          <wrench>0 0 0 0 -0 0</wrench>
        </link>
      </model>
      <model name='ground_plane'>
        <pose frame=''>0 0 0 0 -0 0</pose>
        <scale>1 1 1</scale>
        <link name='link'>
          <pose frame=''>0 0 0 0 -0 0</pose>
          <velocity>0 0 0 0 -0 0</velocity>
          <acceleration>0 0 0 0 -0 0</acceleration>
          <wrench>0 0 0 0 -0 0</wrench>
        </link>
      </model>
      <model name='prius_hybrid'>
        <pose frame=''>43.8834 17.6964 0.709561 -0.201206 0.208678 -2.7973</pose>
        <scale>1 1 1</scale>
        <link name='chassis'>
          <pose frame=''>43.8834 17.6964 0.709561 -0.201206 0.208678 -2.7973</pose>
          <velocity>-4.78983 5.5461 -10.7909 0.139582 -0.975861 2.89057</velocity>
          <acceleration>-1834.84 5069.7 -120.913 -2.26215 1.14093 -0.908636</acceleration>
          <wrench>-2.433e+06 6.72242e+06 -160330 0 -0 0</wrench>
        </link>
        <link name='front_left_wheel'>
          <pose frame=''>42.6627 18.7622 1.2597 0.465437 0.340705 -2.03723</pose>
          <velocity>-5.56886 -18.0454 -32.1975 -2.08821 1.13365 -0.052854</velocity>
          <acceleration>1261.45 4656.56 7293.34 3.05204 0.211032 -0.593456</acceleration>
          <wrench>13876 51222.1 80226.7 0 -0 0</wrench>
        </link>
        <link name='front_right_wheel'>
          <pose frame=''>43.9524 19.0763 1.30817 0.261757 0.546408 -2.73295</pose>
          <velocity>26.0727 27.3117 18.3644 3.10861 -0.851862 2.86317</velocity>
          <acceleration>-7500.48 4688.49 -17427.7 1.9206 -0.303696 2.30149</acceleration>
          <wrench>-82505.3 51573.4 -191705 0 -0 0</wrench>
        </link>
        <link name='rear_axle'>
          <pose frame=''>44.38 16.345 0.771257 -1.25159 0.168566 -2.80489</pose>
          <velocity>-4.21983 0.532925 -29.891 -0.181746 0.911853 -1.30885</velocity>
          <acceleration>9845.12 11109.5 15570.4 0.741814 0.523648 0.444971</acceleration>
          <wrench>295354 333286 467113 0 -0 0</wrench>
        </link>
        <link name='rear_left_wheel'>
          <pose frame=''>43.5115 16.2715 0.879615 -0.557572 -0.385884 -2.92962</pose>
          <velocity>30.1779 -75.2844 -93.8014 -1.68551 1.11409 2.74701</velocity>
          <acceleration>38331.5 -92960.9 9011.44 1.83509 0.234857 -2.63558</acceleration>
          <wrench>421646 -1.02257e+06 99125.9 0 -0 0</wrench>
        </link>
        <link name='rear_right_wheel'>
          <pose frame=''>45.1987 16.0773 0.320776 -1.50868 -0.381239 2.50473</pose>
          <velocity>37.5939 88.4465 66.523 -2.86136 -1.45453 -0.88878</velocity>
          <acceleration>17243.8 46863 28387.7 1.85023 -0.214616 1.54849</acceleration>
          <wrench>189682 515493 312265 0 -0 0</wrench>
        </link>
        <link name='steering_wheel'>
          <pose frame=''>43.2578 17.9715 1.83353 -1.422 -1.33164 -2.97937</pose>
          <velocity>-4.23279 -9.87025 -34.964 -1.58937 -0.095839 -0.843498</velocity>
          <acceleration>8460.97 11730 10333.8 -0.188727 -0.06926 -1.10412</acceleration>
          <wrench>8460.97 11730 10333.8 0 -0 0</wrench>
        </link>
      </model>
      <model name='prius_hybrid_0'>
        <pose frame=''>102.695 -13.8704 0.111641 -2e-06 -0 3.14083</pose>
        <scale>1 1 1</scale>
        <link name='chassis'>
          <pose frame=''>102.695 -13.8704 0.111641 -2e-06 -0 3.14083</pose>
          <velocity>-7e-06 -0.000155 -1.9e-05 -9.5e-05 4e-06 -3e-06</velocity>
          <acceleration>0.000613 0.013628 -0.064542 -0.205012 0.009273 0.001831</acceleration>
          <wrench>0.812757 18.0708 -85.5832 0 -0 0</wrench>
        </link>
        <link name='front_left_wheel'>
          <pose frame=''>101.936 -12.4598 0.411646 -0.001654 0.001279 -3.12774</pose>
          <velocity>-1e-06 -5.2e-05 -0.000158 0.000163 -2e-06 -0.000152</velocity>
          <acceleration>-0.001706 8.3e-05 -0.251126 -0.004731 -0.005231 -0.001597</acceleration>
          <wrench>-0.018761 0.00091 -2.76239 0 -0 0</wrench>
        </link>
        <link name='front_right_wheel'>
          <pose frame=''>103.456 -12.461 0.411646 -0.00122 6.3e-05 3.14154</pose>
          <velocity>-0 -5.5e-05 -0.000166 0.00017 1e-06 -0.000148</velocity>
          <acceleration>-0.001845 0.001391 -0.264555 -0.008879 -0.005638 0.004371</acceleration>
          <wrench>-0.020294 0.015299 -2.9101 0 -0 0</wrench>
        </link>
        <link name='rear_axle'>
          <pose frame=''>102.694 -15.3204 0.411637 -2e-06 -5e-06 3.14083</pose>
          <velocity>-1.1e-05 -0.000129 0.000116 -0.000306 1.5e-05 -7e-06</velocity>
          <acceleration>0.001901 -0.023906 0.30426 -0.243599 -0.067059 0.000653</acceleration>
          <wrench>0.057044 -0.717183 9.1278 0 -0 0</wrench>
        </link>
        <link name='rear_left_wheel'>
          <pose frame=''>101.908 -15.3198 0.411647 -0.001607 -3e-06 3.14083</pose>
          <velocity>-7e-06 -0.000115 0.000151 0.000368 -1.9e-05 1.1e-05</velocity>
          <acceleration>-0.003143 -0.025852 0.148281 0.082292 -0.010785 0.005758</acceleration>
          <wrench>-0.034573 -0.284373 1.63109 0 -0 0</wrench>
        </link>
        <link name='rear_right_wheel'>
          <pose frame=''>103.48 -15.321 0.411647 -0.001113 8e-06 3.14083</pose>
          <velocity>-1e-05 -6.9e-05 0.00015 0.000216 -3e-05 2.1e-05</velocity>
          <acceleration>0.010652 -0.010518 0.144587 0.031604 0.035486 0.005985</acceleration>
          <wrench>0.11717 -0.115696 1.59046 0 -0 0</wrench>
        </link>
        <link name='steering_wheel'>
          <pose frame=''>102.338 -13.2424 1.09947 -1.29584 0.211152 -3.08328</pose>
          <velocity>-1e-06 -6e-05 -7.8e-05 -9.6e-05 -0.000562 0.000153</velocity>
          <acceleration>0.004999 0.116966 -0.136644 -0.20527 -0.159246 0.042275</acceleration>
          <wrench>0.004999 0.116966 -0.136644 0 -0 0</wrench>
        </link>
      </model>
      <model name='prius_hybrid_1'>
        <pose frame=''>38.6526 55.9496 0.011641 -2e-06 -0 1e-05</pose>
        <scale>1 1 1</scale>
        <link name='chassis'>
          <pose frame=''>38.6526 55.9496 0.011641 -2e-06 -0 1e-05</pose>
          <velocity>9e-06 1.7e-05 2.1e-05 -3e-06 -0 5e-06</velocity>
          <acceleration>0 -0 -0 0 -0 0</acceleration>
          <wrench>3e-06 -1.2e-05 -0 0 -0 0</wrench>
        </link>
        <link name='front_left_wheel'>
          <pose frame=''>39.4126 54.5396 0.311646 -0.000188 0.000103 0.001186</pose>
          <velocity>1.6e-05 2.3e-05 3.2e-05 -7.1e-05 4.9e-05 0.000567</velocity>
          <acceleration>0 -0 0 0 -0 1e-06</acceleration>
          <wrench>0 -0 0 0 -0 0</wrench>
        </link>
        <link name='front_right_wheel'>
          <pose frame=''>37.8926 54.5395 0.311646 -0.00014 0.000101 0.001161</pose>
          <velocity>1.6e-05 1.5e-05 3.1e-05 -4.7e-05 4.8e-05 0.000558</velocity>
          <acceleration>0 -0 0 0 -0 0</acceleration>
          <wrench>0 -0 0 0 -0 0</wrench>
        </link>
        <link name='rear_axle'>
          <pose frame=''>38.6526 57.3996 0.311637 -2e-06 -4e-06 1e-05</pose>
          <velocity>1e-06 1.8e-05 1.5e-05 -4e-06 -4e-06 5e-06</velocity>
          <acceleration>0 -0 -0 -1.2e-05 0 0</acceleration>
          <wrench>0 -0 -0 0 -0 0</wrench>
        </link>
        <link name='rear_left_wheel'>
          <pose frame=''>39.4386 57.3996 0.311647 -0.000192 -3e-06 1e-05</pose>
          <velocity>1e-06 2.2e-05 2.5e-05 -7.1e-05 -1e-06 5e-06</velocity>
          <acceleration>-0 -0 -0 0 -0 0</acceleration>
          <wrench>-0 -0 -0 0 -0 0</wrench>
        </link>
        <link name='rear_right_wheel'>
          <pose frame=''>37.8666 57.3995 0.311647 -0.000142 8e-06 1e-05</pose>
          <velocity>2e-06 1.5e-05 2.5e-05 -4.7e-05 2e-06 5e-06</velocity>
          <acceleration>0 -0 0 0 -0 0</acceleration>
          <wrench>0 -0 0 0 -0 0</wrench>
        </link>
        <link name='steering_wheel'>
          <pose frame=''>39.0104 55.3217 0.999795 -1.30183 0.0448 0.012359</pose>
          <velocity>1e-05 3.2e-05 -1.4e-05 -3e-06 0.0182 0.005018</velocity>
          <acceleration>-1e-06 -0 0 0 0.024005 0.000881</acceleration>
          <wrench>-1e-06 -0 0 0 -0 0</wrench>
        </link>
      </model>
      <model name='radio_tower'>
        <pose frame=''>-0.00335 -0.039272 0 0 -0 0</pose>
        <scale>1 1 1</scale>
        <link name='link'>
          <pose frame=''>-0.00335 -0.039272 0 0 -0 0</pose>
          <velocity>0 0 0 0 -0 0</velocity>
          <acceleration>0 0 0 0 -0 0</acceleration>
          <wrench>0 0 0 0 -0 0</wrench>
        </link>
      </model>
      <model name='stop_light_post'>
        <pose frame=''>-55.5907 -5.48002 0 0 0 -1.57079</pose>
        <scale>1 1 1</scale>
        <link name='center_light::link'>
          <pose frame=''>-55.5507 -3.48002 5.82 0 -0 -1.57079</pose>
          <velocity>0 0 0 0 -0 0</velocity>
          <acceleration>0 0 0 0 -0 0</acceleration>
          <wrench>0 0 0 0 -0 0</wrench>
        </link>
        <link name='link'>
          <pose frame=''>-55.5907 -5.48002 0 0 -0 -1.57079</pose>
          <velocity>0 0 0 0 -0 0</velocity>
          <acceleration>0 0 0 0 -0 0</acceleration>
          <wrench>0 0 0 0 -0 0</wrench>
        </link>
        <link name='right_light::link'>
          <pose frame=''>-55.6407 -5.48002 4 0 -0 -1.57079</pose>
          <velocity>0 0 0 0 -0 0</velocity>
          <acceleration>0 0 0 0 -0 0</acceleration>
          <wrench>0 0 0 0 -0 0</wrench>
        </link>
      </model>
      <model name='stop_light_post_0'>
        <pose frame=''>5.18206 -56.0078 0 0 0 -3e-06</pose>
        <scale>1 1 1</scale>
        <link name='center_light::link'>
          <pose frame=''>3.18206 -55.9678 5.82 0 0 -3e-06</pose>
          <velocity>0 0 0 0 -0 0</velocity>
          <acceleration>0 0 0 0 -0 0</acceleration>
          <wrench>0 0 0 0 -0 0</wrench>
        </link>
        <link name='link'>
          <pose frame=''>5.18206 -56.0078 0 0 0 -3e-06</pose>
          <velocity>0 0 0 0 -0 0</velocity>
          <acceleration>0 0 0 0 -0 0</acceleration>
          <wrench>0 0 0 0 -0 0</wrench>
        </link>
        <link name='right_light::link'>
          <pose frame=''>5.18206 -56.0578 4 0 0 -3e-06</pose>
          <velocity>0 0 0 0 -0 0</velocity>
          <acceleration>0 0 0 0 -0 0</acceleration>
          <wrench>0 0 0 0 -0 0</wrench>
        </link>
      </model>
      <model name='stop_light_post_1'>
        <pose frame=''>-5.24695 56.1984 0.062896 0 -0 3.14159</pose>
        <scale>1 1 1</scale>
        <link name='center_light::link'>
          <pose frame=''>-3.24695 56.1584 5.8829 0 -0 3.14159</pose>
          <velocity>0 0 0 0 -0 0</velocity>
          <acceleration>0 0 0 0 -0 0</acceleration>
          <wrench>0 0 0 0 -0 0</wrench>
        </link>
        <link name='link'>
          <pose frame=''>-5.24695 56.1984 0.062896 0 -0 3.14159</pose>
          <velocity>0 0 0 0 -0 0</velocity>
          <acceleration>0 0 0 0 -0 0</acceleration>
          <wrench>0 0 0 0 -0 0</wrench>
        </link>
        <link name='right_light::link'>
          <pose frame=''>-5.24695 56.2484 4.0629 0 -0 3.14159</pose>
          <velocity>0 0 0 0 -0 0</velocity>
          <acceleration>0 0 0 0 -0 0</acceleration>
          <wrench>0 0 0 0 -0 0</wrench>
        </link>
      </model>
      <model name='stop_light_post_2'>
        <pose frame=''>55.2428 5.02323 0 0 -0 1.57079</pose>
        <scale>1 1 1</scale>
        <link name='center_light::link'>
          <pose frame=''>55.2028 3.02323 5.82 0 -0 1.57079</pose>
          <velocity>0 0 0 0 -0 0</velocity>
          <acceleration>0 0 0 0 -0 0</acceleration>
          <wrench>0 0 0 0 -0 0</wrench>
        </link>
        <link name='link'>
          <pose frame=''>55.2428 5.02323 0 0 -0 1.57079</pose>
          <velocity>0 0 0 0 -0 0</velocity>
          <acceleration>0 0 0 0 -0 0</acceleration>
          <wrench>0 0 0 0 -0 0</wrench>
        </link>
        <link name='right_light::link'>
          <pose frame=''>55.2928 5.02323 4 0 -0 1.57079</pose>
          <velocity>0 0 0 0 -0 0</velocity>
          <acceleration>0 0 0 0 -0 0</acceleration>
          <wrench>0 0 0 0 -0 0</wrench>
        </link>
      </model>
      <light name='sun'>
        <pose frame=''>0 0 10 0 -0 0</pose>
      </light>
    </state>
    <gui fullscreen='0'>
      <camera name='user_camera'>
        <pose frame=''>59.0746 265.701 140.037 0 0.541794 -1.86883</pose>
        <view_controller>orbit</view_controller>
        <projection_type>perspective</projection_type>
      </camera>
    </gui>
    <model name='(DS) Curved Road - 100m'>
      <static>1</static>
      <link name='link'>
        <inertial>
          <pose frame=''>0 0 0 0 -0 0</pose>
          <mass>1</mass>
          <inertia>
            <ixx>1</ixx>
            <iyy>1</iyy>
            <izz>1</izz>
            <ixy>0</ixy>
            <ixz>0</ixz>
            <iyz>0</iyz>
          </inertia>
        </inertial>
        <collision name='collision'>
          <geometry>
            <mesh>
              <uri>model://ds_curved_road_100m/meshes/curved_road_100m.dae</uri>
            </mesh>
          </geometry>
          <max_contacts>10</max_contacts>
          <surface>
            <contact>
              <ode/>
            </contact>
            <bounce/>
            <friction>
              <torsional>
                <ode/>
              </torsional>
              <ode/>
            </friction>
          </surface>
        </collision>
        <visual name='visual'>
          <geometry>
            <mesh>
              <uri>model://ds_curved_road_100m/meshes/curved_road_100m.dae</uri>
            </mesh>
          </geometry>
        </visual>
        <self_collide>0</self_collide>
        <enable_wind>0</enable_wind>
        <kinematic>0</kinematic>
      </link>
      <pose frame=''>193.272 59.0741 0 0 -0 0</pose>
    </model>
    <model name='(DS) Curved Road - 100m_0'>
      <static>1</static>
      <link name='link'>
        <inertial>
          <pose frame=''>0 0 0 0 -0 0</pose>
          <mass>1</mass>
          <inertia>
            <ixx>1</ixx>
            <iyy>1</iyy>
            <izz>1</izz>
            <ixy>0</ixy>
            <ixz>0</ixz>
            <iyz>0</iyz>
          </inertia>
        </inertial>
        <collision name='collision'>
          <geometry>
            <mesh>
              <uri>model://ds_curved_road_100m/meshes/curved_road_100m.dae</uri>
            </mesh>
          </geometry>
          <max_contacts>10</max_contacts>
          <surface>
            <contact>
              <ode/>
            </contact>
            <bounce/>
            <friction>
              <torsional>
                <ode/>
              </torsional>
              <ode/>
            </friction>
          </surface>
        </collision>
        <visual name='visual'>
          <geometry>
            <mesh>
              <uri>model://ds_curved_road_100m/meshes/curved_road_100m.dae</uri>
            </mesh>
          </geometry>
        </visual>
        <self_collide>0</self_collide>
        <enable_wind>0</enable_wind>
        <kinematic>0</kinematic>
      </link>
      <pose frame=''>79.3767 70.8176 0 0 -0 0</pose>
    </model>
    <model name='(DS) Curved Road - 100m_1'>
      <static>1</static>
      <link name='link'>
        <inertial>
          <pose frame=''>0 0 0 0 -0 0</pose>
          <mass>1</mass>
          <inertia>
            <ixx>1</ixx>
            <iyy>1</iyy>
            <izz>1</izz>
            <ixy>0</ixy>
            <ixz>0</ixz>
            <iyz>0</iyz>
          </inertia>
        </inertial>
        <collision name='collision'>
          <geometry>
            <mesh>
              <uri>model://ds_curved_road_100m/meshes/curved_road_100m.dae</uri>
            </mesh>
          </geometry>
          <max_contacts>10</max_contacts>
          <surface>
            <contact>
              <ode/>
            </contact>
            <bounce/>
            <friction>
              <torsional>
                <ode/>
              </torsional>
              <ode/>
            </friction>
          </surface>
        </collision>
        <visual name='visual'>
          <geometry>
            <mesh>
              <uri>model://ds_curved_road_100m/meshes/curved_road_100m.dae</uri>
            </mesh>
          </geometry>
        </visual>
        <self_collide>0</self_collide>
        <enable_wind>0</enable_wind>
        <kinematic>0</kinematic>
      </link>
      <pose frame=''>-25.0718 128.152 0 0 -0 0</pose>
    </model>
    <model name='(DS) Curved Road - 50m'>
      <static>1</static>
      <link name='link'>
        <inertial>
          <pose frame=''>0 0 0 0 -0 0</pose>
          <mass>1</mass>
          <inertia>
            <ixx>1</ixx>
            <iyy>1</iyy>
            <izz>1</izz>
            <ixy>0</ixy>
            <ixz>0</ixz>
            <iyz>0</iyz>
          </inertia>
        </inertial>
        <collision name='collision'>
          <geometry>
            <mesh>
              <uri>model://ds_curved_road_50m/meshes/curved_road_50m.dae</uri>
            </mesh>
          </geometry>
          <max_contacts>10</max_contacts>
          <surface>
            <contact>
              <ode/>
            </contact>
            <bounce/>
            <friction>
              <torsional>
                <ode/>
              </torsional>
              <ode/>
            </friction>
          </surface>
        </collision>
        <visual name='visual'>
          <geometry>
            <mesh>
              <uri>model://ds_curved_road_50m/meshes/curved_road_50m.dae</uri>
            </mesh>
          </geometry>
        </visual>
        <self_collide>0</self_collide>
        <enable_wind>0</enable_wind>
        <kinematic>0</kinematic>
      </link>
      <pose frame=''>29.9588 -2.41772 0 0 -0 0</pose>
    </model>
    <model name='(DS) Curved Road - 50m_0'>
      <static>1</static>
      <link name='link'>
        <inertial>
          <pose frame=''>0 0 0 0 -0 0</pose>
          <mass>1</mass>
          <inertia>
            <ixx>1</ixx>
            <iyy>1</iyy>
            <izz>1</izz>
            <ixy>0</ixy>
            <ixz>0</ixz>
            <iyz>0</iyz>
          </inertia>
        </inertial>
        <collision name='collision'>
          <geometry>
            <mesh>
              <uri>model://ds_curved_road_50m/meshes/curved_road_50m.dae</uri>
            </mesh>
          </geometry>
          <max_contacts>10</max_contacts>
          <surface>
            <contact>
              <ode/>
            </contact>
            <bounce/>
            <friction>
              <torsional>
                <ode/>
              </torsional>
              <ode/>
            </friction>
          </surface>
        </collision>
        <visual name='visual'>
          <geometry>
            <mesh>
              <uri>model://ds_curved_road_50m/meshes/curved_road_50m.dae</uri>
            </mesh>
          </geometry>
        </visual>
        <self_collide>0</self_collide>
        <enable_wind>0</enable_wind>
        <kinematic>0</kinematic>
      </link>
      <pose frame=''>-0.085035 -27.2647 0 0 -0 0</pose>
    </model>
    <model name='(DS) Curved Road - 50m_1'>
      <static>1</static>
      <link name='link'>
        <inertial>
          <pose frame=''>0 0 0 0 -0 0</pose>
          <mass>1</mass>
          <inertia>
            <ixx>1</ixx>
            <iyy>1</iyy>
            <izz>1</izz>
            <ixy>0</ixy>
            <ixz>0</ixz>
            <iyz>0</iyz>
          </inertia>
        </inertial>
        <collision name='collision'>
          <geometry>
            <mesh>
              <uri>model://ds_curved_road_50m/meshes/curved_road_50m.dae</uri>
            </mesh>
          </geometry>
          <max_contacts>10</max_contacts>
          <surface>
            <contact>
              <ode/>
            </contact>
            <bounce/>
            <friction>
              <torsional>
                <ode/>
              </torsional>
              <ode/>
            </friction>
          </surface>
        </collision>
        <visual name='visual'>
          <geometry>
            <mesh>
              <uri>model://ds_curved_road_50m/meshes/curved_road_50m.dae</uri>
            </mesh>
          </geometry>
        </visual>
        <self_collide>0</self_collide>
        <enable_wind>0</enable_wind>
        <kinematic>0</kinematic>
      </link>
      <pose frame=''>-39.2543 -27.8784 0 0 -0 0</pose>
    </model>
    <model name='(DS) Curved Road - 50m_2'>
      <static>1</static>
      <link name='link'>
        <inertial>
          <pose frame=''>0 0 0 0 -0 0</pose>
          <mass>1</mass>
          <inertia>
            <ixx>1</ixx>
            <iyy>1</iyy>
            <izz>1</izz>
            <ixy>0</ixy>
            <ixz>0</ixz>
            <iyz>0</iyz>
          </inertia>
        </inertial>
        <collision name='collision'>
          <geometry>
            <mesh>
              <uri>model://ds_curved_road_50m/meshes/curved_road_50m.dae</uri>
            </mesh>
          </geometry>
          <max_contacts>10</max_contacts>
          <surface>
            <contact>
              <ode/>
            </contact>
            <bounce/>
            <friction>
              <torsional>
                <ode/>
              </torsional>
              <ode/>
            </friction>
          </surface>
        </collision>
        <visual name='visual'>
          <geometry>
            <mesh>
              <uri>model://ds_curved_road_50m/meshes/curved_road_50m.dae</uri>
            </mesh>
          </geometry>
        </visual>
        <self_collide>0</self_collide>
        <enable_wind>0</enable_wind>
        <kinematic>0</kinematic>
      </link>
      <pose frame=''>-70.2253 40.3122 0 0 -0 0</pose>
    </model>
    <model name='(DS) Curved Road - 100m_3'>
      <static>1</static>
      <link name='link'>
        <inertial>
          <pose frame=''>0 0 0 0 -0 0</pose>
          <mass>1</mass>
          <inertia>
            <ixx>1</ixx>
            <iyy>1</iyy>
            <izz>1</izz>
            <ixy>0</ixy>
            <ixz>0</ixz>
            <iyz>0</iyz>
          </inertia>
        </inertial>
        <collision name='collision'>
          <geometry>
            <mesh>
              <uri>model://ds_curved_road_100m/meshes/curved_road_100m.dae</uri>
            </mesh>
          </geometry>
          <max_contacts>10</max_contacts>
          <surface>
            <contact>
              <ode/>
            </contact>
            <bounce/>
            <friction>
              <torsional>
                <ode/>
              </torsional>
              <ode/>
            </friction>
          </surface>
        </collision>
        <visual name='visual'>
          <geometry>
            <mesh>
              <uri>model://ds_curved_road_100m/meshes/curved_road_100m.dae</uri>
            </mesh>
          </geometry>
        </visual>
        <self_collide>0</self_collide>
        <enable_wind>0</enable_wind>
        <kinematic>0</kinematic>
      </link>
      <pose frame=''>-0.705665 131.702 0 0 -0 0</pose>
    </model>
    <model name='(DS) Straight Road - 100m'>
      <static>1</static>
      <link name='link'>
        <inertial>
          <pose frame=''>0 0 0 0 -0 0</pose>
          <mass>1</mass>
          <inertia>
            <ixx>1</ixx>
            <iyy>1</iyy>
            <izz>1</izz>
            <ixy>0</ixy>
            <ixz>0</ixz>
            <iyz>0</iyz>
          </inertia>
        </inertial>
        <collision name='collision'>
          <geometry>
            <mesh>
              <uri>model://ds_straight_road_100m/meshes/straight_road_100m.dae</uri>
            </mesh>
          </geometry>
          <max_contacts>10</max_contacts>
          <surface>
            <contact>
              <ode/>
            </contact>
            <bounce/>
            <friction>
              <torsional>
                <ode/>
              </torsional>
              <ode/>
            </friction>
          </surface>
        </collision>
        <visual name='visual'>
          <geometry>
            <mesh>
              <uri>model://ds_straight_road_100m/meshes/straight_road_100m.dae</uri>
            </mesh>
          </geometry>
        </visual>
        <self_collide>0</self_collide>
        <enable_wind>0</enable_wind>
        <kinematic>0</kinematic>
      </link>
      <pose frame=''>105.941 20.1032 0 0 -0 0</pose>
    </model>
    <model name='(DS) Straight Road - 50m'>
      <static>1</static>
      <link name='link'>
        <inertial>
          <pose frame=''>0 0 0 0 -0 0</pose>
          <mass>1</mass>
          <inertia>
            <ixx>1</ixx>
            <iyy>1</iyy>
            <izz>1</izz>
            <ixy>0</ixy>
            <ixz>0</ixz>
            <iyz>0</iyz>
          </inertia>
        </inertial>
        <collision name='collision'>
          <geometry>
            <mesh>
              <uri>model://ds_straight_road_50m/meshes/straight_road_50m.dae</uri>
            </mesh>
          </geometry>
          <max_contacts>10</max_contacts>
          <surface>
            <contact>
              <ode/>
            </contact>
            <bounce/>
            <friction>
              <torsional>
                <ode/>
              </torsional>
              <ode/>
            </friction>
          </surface>
        </collision>
        <visual name='visual'>
          <geometry>
            <mesh>
              <uri>model://ds_straight_road_50m/meshes/straight_road_50m.dae</uri>
            </mesh>
          </geometry>
        </visual>
        <self_collide>0</self_collide>
        <enable_wind>0</enable_wind>
        <kinematic>0</kinematic>
      </link>
      <pose frame=''>74.9763 7.62509 0 0 -0 0</pose>
    </model>
    <model name='(DS) Straight Road - 100m_0'>
      <static>1</static>
      <link name='link'>
        <inertial>
          <pose frame=''>0 0 0 0 -0 0</pose>
          <mass>1</mass>
          <inertia>
            <ixx>1</ixx>
            <iyy>1</iyy>
            <izz>1</izz>
            <ixy>0</ixy>
            <ixz>0</ixz>
            <iyz>0</iyz>
          </inertia>
        </inertial>
        <collision name='collision'>
          <geometry>
            <mesh>
              <uri>model://ds_straight_road_100m/meshes/straight_road_100m.dae</uri>
            </mesh>
          </geometry>
          <max_contacts>10</max_contacts>
          <surface>
            <contact>
              <ode/>
            </contact>
            <bounce/>
            <friction>
              <torsional>
                <ode/>
              </torsional>
              <ode/>
            </friction>
          </surface>
        </collision>
        <visual name='visual'>
          <geometry>
            <mesh>
              <uri>model://ds_straight_road_100m/meshes/straight_road_100m.dae</uri>
            </mesh>
          </geometry>
        </visual>
        <self_collide>0</self_collide>
        <enable_wind>0</enable_wind>
        <kinematic>0</kinematic>
      </link>
      <pose frame=''>-104.177 7.8925 0 0 -0 0</pose>
    </model>
    <model name='(DS) Straight Road - 50m_0'>
      <static>1</static>
      <link name='link'>
        <inertial>
          <pose frame=''>0 0 0 0 -0 0</pose>
          <mass>1</mass>
          <inertia>
            <ixx>1</ixx>
            <iyy>1</iyy>
            <izz>1</izz>
            <ixy>0</ixy>
            <ixz>0</ixz>
            <iyz>0</iyz>
          </inertia>
        </inertial>
        <collision name='collision'>
          <geometry>
            <mesh>
              <uri>model://ds_straight_road_50m/meshes/straight_road_50m.dae</uri>
            </mesh>
          </geometry>
          <max_contacts>10</max_contacts>
          <surface>
            <contact>
              <ode/>
            </contact>
            <bounce/>
            <friction>
              <torsional>
                <ode/>
              </torsional>
              <ode/>
            </friction>
          </surface>
        </collision>
        <visual name='visual'>
          <geometry>
            <mesh>
              <uri>model://ds_straight_road_50m/meshes/straight_road_50m.dae</uri>
            </mesh>
          </geometry>
        </visual>
        <self_collide>0</self_collide>
        <enable_wind>0</enable_wind>
        <kinematic>0</kinematic>
      </link>
      <pose frame=''>-76.4645 6.9166 0 0 -0 0</pose>
    </model>
    <model name='(DS) Straight Road - 50m_1'>
      <static>1</static>
      <link name='link'>
        <inertial>
          <pose frame=''>0 0 0 0 -0 0</pose>
          <mass>1</mass>
          <inertia>
            <ixx>1</ixx>
            <iyy>1</iyy>
            <izz>1</izz>
            <ixy>0</ixy>
            <ixz>0</ixz>
            <iyz>0</iyz>
          </inertia>
        </inertial>
        <collision name='collision'>
          <geometry>
            <mesh>
              <uri>model://ds_straight_road_50m/meshes/straight_road_50m.dae</uri>
            </mesh>
          </geometry>
          <max_contacts>10</max_contacts>
          <surface>
            <contact>
              <ode/>
            </contact>
            <bounce/>
            <friction>
              <torsional>
                <ode/>
              </torsional>
              <ode/>
            </friction>
          </surface>
        </collision>
        <visual name='visual'>
          <geometry>
            <mesh>
              <uri>model://ds_straight_road_50m/meshes/straight_road_50m.dae</uri>
            </mesh>
          </geometry>
        </visual>
        <self_collide>0</self_collide>
        <enable_wind>0</enable_wind>
        <kinematic>0</kinematic>
      </link>
      <pose frame=''>2.11033 89.787 0 0 -0 0</pose>
    </model>
    <model name='(DS) Straight Road - 50m_2'>
      <static>1</static>
      <link name='link'>
        <inertial>
          <pose frame=''>0 0 0 0 -0 0</pose>
          <mass>1</mass>
          <inertia>
            <ixx>1</ixx>
            <iyy>1</iyy>
            <izz>1</izz>
            <ixy>0</ixy>
            <ixz>0</ixz>
            <iyz>0</iyz>
          </inertia>
        </inertial>
        <collision name='collision'>
          <geometry>
            <mesh>
              <uri>model://ds_straight_road_50m/meshes/straight_road_50m.dae</uri>
            </mesh>
          </geometry>
          <max_contacts>10</max_contacts>
          <surface>
            <contact>
              <ode/>
            </contact>
            <bounce/>
            <friction>
              <torsional>
                <ode/>
              </torsional>
              <ode/>
            </friction>
          </surface>
        </collision>
        <visual name='visual'>
          <geometry>
            <mesh>
              <uri>model://ds_straight_road_50m/meshes/straight_road_50m.dae</uri>
            </mesh>
          </geometry>
        </visual>
        <self_collide>0</self_collide>
        <enable_wind>0</enable_wind>
        <kinematic>0</kinematic>
      </link>
      <pose frame=''>1.33899 -73.3109 0 0 -0 0</pose>
    </model>
    <model name='Fast Food'>
      <static>1</static>
      <link name='link'>
        <pose frame=''>0 0 3.15931 0 -0 0</pose>
        <collision name='collision'>
          <geometry>
            <mesh>
              <scale>3 3 2</scale>
              <uri>model://fast_food/meshes/fast_food.dae</uri>
            </mesh>
          </geometry>
          <max_contacts>10</max_contacts>
          <surface>
            <contact>
              <ode/>
            </contact>
            <bounce/>
            <friction>
              <torsional>
                <ode/>
              </torsional>
              <ode/>
            </friction>
          </surface>
        </collision>
        <visual name='visual'>
          <geometry>
            <mesh>
              <scale>3 3 2</scale>
              <uri>model://fast_food/meshes/fast_food.dae</uri>
            </mesh>
          </geometry>
          <material>
            <script>
              <uri>model://fast_food/materials/scripts</uri>
              <uri>model://fast_food/materials/textures</uri>
              <name>FastFood/Diffuse</name>
            </script>
            <shader type='normal_map_tangent_space'>
              <normal_map>FastFood_Normal.png</normal_map>
            </shader>
          </material>
        </visual>
        <self_collide>0</self_collide>
        <enable_wind>0</enable_wind>
        <kinematic>0</kinematic>
      </link>
      <pose frame=''>-3.51982 -26.2417 0 0 -0 0</pose>
    </model>
    <model name='Gas Station'>
      <static>1</static>
      <link name='link'>
        <pose frame=''>0 0 0 0 -0 0</pose>
        <collision name='collision'>
          <geometry>
            <mesh>
              <uri>model://gas_station/meshes/gas_station.dae</uri>
            </mesh>
          </geometry>
          <max_contacts>10</max_contacts>
          <surface>
            <contact>
              <ode/>
            </contact>
            <bounce/>
            <friction>
              <torsional>
                <ode/>
              </torsional>
              <ode/>
            </friction>
          </surface>
        </collision>
        <visual name='visual'>
          <geometry>
            <mesh>
              <uri>model://gas_station/meshes/gas_station.dae</uri>
            </mesh>
          </geometry>
          <material>
            <script>
              <uri>model://gas_station/materials/scripts</uri>
              <uri>model://gas_station/materials/textures</uri>
              <name>GasStation/Diffuse</name>
            </script>
            <shader type='normal_map_tangent_space'>
              <normal_map>GasStation_Normal.png</normal_map>
            </shader>
          </material>
        </visual>
        <self_collide>0</self_collide>
        <enable_wind>0</enable_wind>
        <kinematic>0</kinematic>
      </link>
      <pose frame=''>0.672768 114.469 0 0 -0 0</pose>
    </model>
    <model name='stop_light_post'>
      <static>1</static>
      <link name='link'>
        <collision name='post'>
          <geometry>
            <mesh>
              <uri>model://stop_light_post/meshes/stop_light_post.obj</uri>
              <scale>0.01 0.01 0.01</scale>
            </mesh>
          </geometry>
          <max_contacts>10</max_contacts>
          <surface>
            <contact>
              <ode/>
            </contact>
            <bounce/>
            <friction>
              <torsional>
                <ode/>
              </torsional>
              <ode/>
            </friction>
          </surface>
        </collision>
        <visual name='post'>
          <geometry>
            <mesh>
              <uri>model://stop_light_post/meshes/stop_light_post.obj</uri>
              <scale>0.01 0.01 0.01</scale>
            </mesh>
          </geometry>
        </visual>
        <self_collide>0</self_collide>
        <enable_wind>0</enable_wind>
        <kinematic>0</kinematic>
      </link>
      <static>1</static>
      <link name='right_light::link'>
        <collision name='collision'>
          <geometry>
            <mesh>
              <uri>model://stop_light/meshes/stop_light.obj</uri>
              <scale>0.01 0.01 0.01</scale>
            </mesh>
          </geometry>
          <max_contacts>10</max_contacts>
          <surface>
            <contact>
              <ode/>
            </contact>
            <bounce/>
            <friction>
              <torsional>
                <ode/>
              </torsional>
              <ode/>
            </friction>
          </surface>
        </collision>
        <visual name='frame'>
          <geometry>
            <mesh>
              <uri>model://stop_light/meshes/stop_light.obj</uri>
              <scale>0.01 0.01 0.01</scale>
            </mesh>
          </geometry>
        </visual>
        <visual name='red'>
          <pose frame=''>-0.001123 -0.082251 -0.147514 0 -0 0</pose>
          <geometry>
            <sphere>
              <radius>0.1012</radius>
            </sphere>
          </geometry>
          <material>
            <script>
              <uri>model://stop_light/materials/scripts/</uri>
              <uri>model://stop_light/materials/textures/</uri>
              <name>StopLight/Light</name>
            </script>
            <ambient>1 0 0 1</ambient>
            <specular>1 0 0 1</specular>
          </material>
        </visual>
        <visual name='yellow'>
          <pose frame=''>-0.001123 -0.082251 -0.402 0 -0 0</pose>
          <geometry>
            <sphere>
              <radius>0.1012</radius>
            </sphere>
          </geometry>
          <material>
            <script>
              <uri>model://stop_light/materials/scripts/</uri>
              <uri>model://stop_light/materials/textures/</uri>
              <name>StopLight/Light</name>
            </script>
            <ambient>1 1 0 1</ambient>
            <specular>1 1 0 1</specular>
          </material>
        </visual>
        <visual name='green'>
          <pose frame=''>-0.001123 -0.082251 -0.655 0 -0 0</pose>
          <geometry>
            <sphere>
              <radius>0.1012</radius>
            </sphere>
          </geometry>
          <material>
            <script>
              <uri>model://stop_light/materials/scripts/</uri>
              <uri>model://stop_light/materials/textures/</uri>
              <name>StopLight/Light</name>
            </script>
            <ambient>0 1 0 1</ambient>
            <specular>0 1 0 1</specular>
          </material>
        </visual>
        <pose frame=''>0 -0.05 4 0 -0 0</pose>
        <self_collide>0</self_collide>
        <enable_wind>0</enable_wind>
        <kinematic>0</kinematic>
      </link>
      <static>1</static>
      <link name='center_light::link'>
        <collision name='collision'>
          <geometry>
            <mesh>
              <uri>model://stop_light/meshes/stop_light.obj</uri>
              <scale>0.01 0.01 0.01</scale>
            </mesh>
          </geometry>
          <max_contacts>10</max_contacts>
          <surface>
            <contact>
              <ode/>
            </contact>
            <bounce/>
            <friction>
              <torsional>
                <ode/>
              </torsional>
              <ode/>
            </friction>
          </surface>
        </collision>
        <visual name='frame'>
          <geometry>
            <mesh>
              <uri>model://stop_light/meshes/stop_light.obj</uri>
              <scale>0.01 0.01 0.01</scale>
            </mesh>
          </geometry>
        </visual>
        <visual name='red'>
          <pose frame=''>-0.001123 -0.082251 -0.147514 0 -0 0</pose>
          <geometry>
            <sphere>
              <radius>0.1012</radius>
            </sphere>
          </geometry>
          <material>
            <script>
              <uri>model://stop_light/materials/scripts/</uri>
              <uri>model://stop_light/materials/textures/</uri>
              <name>StopLight/Light</name>
            </script>
            <ambient>1 0 0 1</ambient>
            <specular>1 0 0 1</specular>
          </material>
        </visual>
        <visual name='yellow'>
          <pose frame=''>-0.001123 -0.082251 -0.402 0 -0 0</pose>
          <geometry>
            <sphere>
              <radius>0.1012</radius>
            </sphere>
          </geometry>
          <material>
            <script>
              <uri>model://stop_light/materials/scripts/</uri>
              <uri>model://stop_light/materials/textures/</uri>
              <name>StopLight/Light</name>
            </script>
            <ambient>1 1 0 1</ambient>
            <specular>1 1 0 1</specular>
          </material>
        </visual>
        <visual name='green'>
          <pose frame=''>-0.001123 -0.082251 -0.655 0 -0 0</pose>
          <geometry>
            <sphere>
              <radius>0.1012</radius>
            </sphere>
          </geometry>
          <material>
            <script>
              <uri>model://stop_light/materials/scripts/</uri>
              <uri>model://stop_light/materials/textures/</uri>
              <name>StopLight/Light</name>
            </script>
            <ambient>0 1 0 1</ambient>
            <specular>0 1 0 1</specular>
          </material>
        </visual>
        <pose frame=''>-2 0.04 5.82 0 -0 0</pose>
        <self_collide>0</self_collide>
        <enable_wind>0</enable_wind>
        <kinematic>0</kinematic>
      </link>
      <pose frame=''>-57.3374 4.84981 0 0 -0 0</pose>
    </model>
    <model name='stop_light_post_0'>
      <static>1</static>
      <link name='link'>
        <collision name='post'>
          <geometry>
            <mesh>
              <uri>model://stop_light_post/meshes/stop_light_post.obj</uri>
              <scale>0.01 0.01 0.01</scale>
            </mesh>
          </geometry>
          <max_contacts>10</max_contacts>
          <surface>
            <contact>
              <ode/>
            </contact>
            <bounce/>
            <friction>
              <torsional>
                <ode/>
              </torsional>
              <ode/>
            </friction>
          </surface>
        </collision>
        <visual name='post'>
          <geometry>
            <mesh>
              <uri>model://stop_light_post/meshes/stop_light_post.obj</uri>
              <scale>0.01 0.01 0.01</scale>
            </mesh>
          </geometry>
        </visual>
        <self_collide>0</self_collide>
        <enable_wind>0</enable_wind>
        <kinematic>0</kinematic>
      </link>
      <static>1</static>
      <link name='right_light::link'>
        <collision name='collision'>
          <geometry>
            <mesh>
              <uri>model://stop_light/meshes/stop_light.obj</uri>
              <scale>0.01 0.01 0.01</scale>
            </mesh>
          </geometry>
          <max_contacts>10</max_contacts>
          <surface>
            <contact>
              <ode/>
            </contact>
            <bounce/>
            <friction>
              <torsional>
                <ode/>
              </torsional>
              <ode/>
            </friction>
          </surface>
        </collision>
        <visual name='frame'>
          <geometry>
            <mesh>
              <uri>model://stop_light/meshes/stop_light.obj</uri>
              <scale>0.01 0.01 0.01</scale>
            </mesh>
          </geometry>
        </visual>
        <visual name='red'>
          <pose frame=''>-0.001123 -0.082251 -0.147514 0 -0 0</pose>
          <geometry>
            <sphere>
              <radius>0.1012</radius>
            </sphere>
          </geometry>
          <material>
            <script>
              <uri>model://stop_light/materials/scripts/</uri>
              <uri>model://stop_light/materials/textures/</uri>
              <name>StopLight/Light</name>
            </script>
            <ambient>1 0 0 1</ambient>
            <specular>1 0 0 1</specular>
          </material>
        </visual>
        <visual name='yellow'>
          <pose frame=''>-0.001123 -0.082251 -0.402 0 -0 0</pose>
          <geometry>
            <sphere>
              <radius>0.1012</radius>
            </sphere>
          </geometry>
          <material>
            <script>
              <uri>model://stop_light/materials/scripts/</uri>
              <uri>model://stop_light/materials/textures/</uri>
              <name>StopLight/Light</name>
            </script>
            <ambient>1 1 0 1</ambient>
            <specular>1 1 0 1</specular>
          </material>
        </visual>
        <visual name='green'>
          <pose frame=''>-0.001123 -0.082251 -0.655 0 -0 0</pose>
          <geometry>
            <sphere>
              <radius>0.1012</radius>
            </sphere>
          </geometry>
          <material>
            <script>
              <uri>model://stop_light/materials/scripts/</uri>
              <uri>model://stop_light/materials/textures/</uri>
              <name>StopLight/Light</name>
            </script>
            <ambient>0 1 0 1</ambient>
            <specular>0 1 0 1</specular>
          </material>
        </visual>
        <pose frame=''>0 -0.05 4 0 -0 0</pose>
        <self_collide>0</self_collide>
        <enable_wind>0</enable_wind>
        <kinematic>0</kinematic>
      </link>
      <static>1</static>
      <link name='center_light::link'>
        <collision name='collision'>
          <geometry>
            <mesh>
              <uri>model://stop_light/meshes/stop_light.obj</uri>
              <scale>0.01 0.01 0.01</scale>
            </mesh>
          </geometry>
          <max_contacts>10</max_contacts>
          <surface>
            <contact>
              <ode/>
            </contact>
            <bounce/>
            <friction>
              <torsional>
                <ode/>
              </torsional>
              <ode/>
            </friction>
          </surface>
        </collision>
        <visual name='frame'>
          <geometry>
            <mesh>
              <uri>model://stop_light/meshes/stop_light.obj</uri>
              <scale>0.01 0.01 0.01</scale>
            </mesh>
          </geometry>
        </visual>
        <visual name='red'>
          <pose frame=''>-0.001123 -0.082251 -0.147514 0 -0 0</pose>
          <geometry>
            <sphere>
              <radius>0.1012</radius>
            </sphere>
          </geometry>
          <material>
            <script>
              <uri>model://stop_light/materials/scripts/</uri>
              <uri>model://stop_light/materials/textures/</uri>
              <name>StopLight/Light</name>
            </script>
            <ambient>1 0 0 1</ambient>
            <specular>1 0 0 1</specular>
          </material>
        </visual>
        <visual name='yellow'>
          <pose frame=''>-0.001123 -0.082251 -0.402 0 -0 0</pose>
          <geometry>
            <sphere>
              <radius>0.1012</radius>
            </sphere>
          </geometry>
          <material>
            <script>
              <uri>model://stop_light/materials/scripts/</uri>
              <uri>model://stop_light/materials/textures/</uri>
              <name>StopLight/Light</name>
            </script>
            <ambient>1 1 0 1</ambient>
            <specular>1 1 0 1</specular>
          </material>
        </visual>
        <visual name='green'>
          <pose frame=''>-0.001123 -0.082251 -0.655 0 -0 0</pose>
          <geometry>
            <sphere>
              <radius>0.1012</radius>
            </sphere>
          </geometry>
          <material>
            <script>
              <uri>model://stop_light/materials/scripts/</uri>
              <uri>model://stop_light/materials/textures/</uri>
              <name>StopLight/Light</name>
            </script>
            <ambient>0 1 0 1</ambient>
            <specular>0 1 0 1</specular>
          </material>
        </visual>
        <pose frame=''>-2 0.04 5.82 0 -0 0</pose>
        <self_collide>0</self_collide>
        <enable_wind>0</enable_wind>
        <kinematic>0</kinematic>
      </link>
      <pose frame=''>-4.78967 -56.7832 0 0 -0 0</pose>
    </model>
    <model name='stop_light_post_1'>
      <static>1</static>
      <link name='link'>
        <collision name='post'>
          <geometry>
            <mesh>
              <uri>model://stop_light_post/meshes/stop_light_post.obj</uri>
              <scale>0.01 0.01 0.01</scale>
            </mesh>
          </geometry>
          <max_contacts>10</max_contacts>
          <surface>
            <contact>
              <ode/>
            </contact>
            <bounce/>
            <friction>
              <torsional>
                <ode/>
              </torsional>
              <ode/>
            </friction>
          </surface>
        </collision>
        <visual name='post'>
          <geometry>
            <mesh>
              <uri>model://stop_light_post/meshes/stop_light_post.obj</uri>
              <scale>0.01 0.01 0.01</scale>
            </mesh>
          </geometry>
        </visual>
        <self_collide>0</self_collide>
        <enable_wind>0</enable_wind>
        <kinematic>0</kinematic>
      </link>
      <static>1</static>
      <link name='right_light::link'>
        <collision name='collision'>
          <geometry>
            <mesh>
              <uri>model://stop_light/meshes/stop_light.obj</uri>
              <scale>0.01 0.01 0.01</scale>
            </mesh>
          </geometry>
          <max_contacts>10</max_contacts>
          <surface>
            <contact>
              <ode/>
            </contact>
            <bounce/>
            <friction>
              <torsional>
                <ode/>
              </torsional>
              <ode/>
            </friction>
          </surface>
        </collision>
        <visual name='frame'>
          <geometry>
            <mesh>
              <uri>model://stop_light/meshes/stop_light.obj</uri>
              <scale>0.01 0.01 0.01</scale>
            </mesh>
          </geometry>
        </visual>
        <visual name='red'>
          <pose frame=''>-0.001123 -0.082251 -0.147514 0 -0 0</pose>
          <geometry>
            <sphere>
              <radius>0.1012</radius>
            </sphere>
          </geometry>
          <material>
            <script>
              <uri>model://stop_light/materials/scripts/</uri>
              <uri>model://stop_light/materials/textures/</uri>
              <name>StopLight/Light</name>
            </script>
            <ambient>1 0 0 1</ambient>
            <specular>1 0 0 1</specular>
          </material>
        </visual>
        <visual name='yellow'>
          <pose frame=''>-0.001123 -0.082251 -0.402 0 -0 0</pose>
          <geometry>
            <sphere>
              <radius>0.1012</radius>
            </sphere>
          </geometry>
          <material>
            <script>
              <uri>model://stop_light/materials/scripts/</uri>
              <uri>model://stop_light/materials/textures/</uri>
              <name>StopLight/Light</name>
            </script>
            <ambient>1 1 0 1</ambient>
            <specular>1 1 0 1</specular>
          </material>
        </visual>
        <visual name='green'>
          <pose frame=''>-0.001123 -0.082251 -0.655 0 -0 0</pose>
          <geometry>
            <sphere>
              <radius>0.1012</radius>
            </sphere>
          </geometry>
          <material>
            <script>
              <uri>model://stop_light/materials/scripts/</uri>
              <uri>model://stop_light/materials/textures/</uri>
              <name>StopLight/Light</name>
            </script>
            <ambient>0 1 0 1</ambient>
            <specular>0 1 0 1</specular>
          </material>
        </visual>
        <pose frame=''>0 -0.05 4 0 -0 0</pose>
        <self_collide>0</self_collide>
        <enable_wind>0</enable_wind>
        <kinematic>0</kinematic>
      </link>
      <static>1</static>
      <link name='center_light::link'>
        <collision name='collision'>
          <geometry>
            <mesh>
              <uri>model://stop_light/meshes/stop_light.obj</uri>
              <scale>0.01 0.01 0.01</scale>
            </mesh>
          </geometry>
          <max_contacts>10</max_contacts>
          <surface>
            <contact>
              <ode/>
            </contact>
            <bounce/>
            <friction>
              <torsional>
                <ode/>
              </torsional>
              <ode/>
            </friction>
          </surface>
        </collision>
        <visual name='frame'>
          <geometry>
            <mesh>
              <uri>model://stop_light/meshes/stop_light.obj</uri>
              <scale>0.01 0.01 0.01</scale>
            </mesh>
          </geometry>
        </visual>
        <visual name='red'>
          <pose frame=''>-0.001123 -0.082251 -0.147514 0 -0 0</pose>
          <geometry>
            <sphere>
              <radius>0.1012</radius>
            </sphere>
          </geometry>
          <material>
            <script>
              <uri>model://stop_light/materials/scripts/</uri>
              <uri>model://stop_light/materials/textures/</uri>
              <name>StopLight/Light</name>
            </script>
            <ambient>1 0 0 1</ambient>
            <specular>1 0 0 1</specular>
          </material>
        </visual>
        <visual name='yellow'>
          <pose frame=''>-0.001123 -0.082251 -0.402 0 -0 0</pose>
          <geometry>
            <sphere>
              <radius>0.1012</radius>
            </sphere>
          </geometry>
          <material>
            <script>
              <uri>model://stop_light/materials/scripts/</uri>
              <uri>model://stop_light/materials/textures/</uri>
              <name>StopLight/Light</name>
            </script>
            <ambient>1 1 0 1</ambient>
            <specular>1 1 0 1</specular>
          </material>
        </visual>
        <visual name='green'>
          <pose frame=''>-0.001123 -0.082251 -0.655 0 -0 0</pose>
          <geometry>
            <sphere>
              <radius>0.1012</radius>
            </sphere>
          </geometry>
          <material>
            <script>
              <uri>model://stop_light/materials/scripts/</uri>
              <uri>model://stop_light/materials/textures/</uri>
              <name>StopLight/Light</name>
            </script>
            <ambient>0 1 0 1</ambient>
            <specular>0 1 0 1</specular>
          </material>
        </visual>
        <pose frame=''>-2 0.04 5.82 0 -0 0</pose>
        <self_collide>0</self_collide>
        <enable_wind>0</enable_wind>
        <kinematic>0</kinematic>
      </link>
      <pose frame=''>4.93459 56.6179 0 0 -0 0</pose>
    </model>
    <model name='stop_light_post_2'>
      <static>1</static>
      <link name='link'>
        <collision name='post'>
          <geometry>
            <mesh>
              <uri>model://stop_light_post/meshes/stop_light_post.obj</uri>
              <scale>0.01 0.01 0.01</scale>
            </mesh>
          </geometry>
          <max_contacts>10</max_contacts>
          <surface>
            <contact>
              <ode/>
            </contact>
            <bounce/>
            <friction>
              <torsional>
                <ode/>
              </torsional>
              <ode/>
            </friction>
          </surface>
        </collision>
        <visual name='post'>
          <geometry>
            <mesh>
              <uri>model://stop_light_post/meshes/stop_light_post.obj</uri>
              <scale>0.01 0.01 0.01</scale>
            </mesh>
          </geometry>
        </visual>
        <self_collide>0</self_collide>
        <enable_wind>0</enable_wind>
        <kinematic>0</kinematic>
      </link>
      <static>1</static>
      <link name='right_light::link'>
        <collision name='collision'>
          <geometry>
            <mesh>
              <uri>model://stop_light/meshes/stop_light.obj</uri>
              <scale>0.01 0.01 0.01</scale>
            </mesh>
          </geometry>
          <max_contacts>10</max_contacts>
          <surface>
            <contact>
              <ode/>
            </contact>
            <bounce/>
            <friction>
              <torsional>
                <ode/>
              </torsional>
              <ode/>
            </friction>
          </surface>
        </collision>
        <visual name='frame'>
          <geometry>
            <mesh>
              <uri>model://stop_light/meshes/stop_light.obj</uri>
              <scale>0.01 0.01 0.01</scale>
            </mesh>
          </geometry>
        </visual>
        <visual name='red'>
          <pose frame=''>-0.001123 -0.082251 -0.147514 0 -0 0</pose>
          <geometry>
            <sphere>
              <radius>0.1012</radius>
            </sphere>
          </geometry>
          <material>
            <script>
              <uri>model://stop_light/materials/scripts/</uri>
              <uri>model://stop_light/materials/textures/</uri>
              <name>StopLight/Light</name>
            </script>
            <ambient>1 0 0 1</ambient>
            <specular>1 0 0 1</specular>
          </material>
        </visual>
        <visual name='yellow'>
          <pose frame=''>-0.001123 -0.082251 -0.402 0 -0 0</pose>
          <geometry>
            <sphere>
              <radius>0.1012</radius>
            </sphere>
          </geometry>
          <material>
            <script>
              <uri>model://stop_light/materials/scripts/</uri>
              <uri>model://stop_light/materials/textures/</uri>
              <name>StopLight/Light</name>
            </script>
            <ambient>1 1 0 1</ambient>
            <specular>1 1 0 1</specular>
          </material>
        </visual>
        <visual name='green'>
          <pose frame=''>-0.001123 -0.082251 -0.655 0 -0 0</pose>
          <geometry>
            <sphere>
              <radius>0.1012</radius>
            </sphere>
          </geometry>
          <material>
            <script>
              <uri>model://stop_light/materials/scripts/</uri>
              <uri>model://stop_light/materials/textures/</uri>
              <name>StopLight/Light</name>
            </script>
            <ambient>0 1 0 1</ambient>
            <specular>0 1 0 1</specular>
          </material>
        </visual>
        <pose frame=''>0 -0.05 4 0 -0 0</pose>
        <self_collide>0</self_collide>
        <enable_wind>0</enable_wind>
        <kinematic>0</kinematic>
      </link>
      <static>1</static>
      <link name='center_light::link'>
        <collision name='collision'>
          <geometry>
            <mesh>
              <uri>model://stop_light/meshes/stop_light.obj</uri>
              <scale>0.01 0.01 0.01</scale>
            </mesh>
          </geometry>
          <max_contacts>10</max_contacts>
          <surface>
            <contact>
              <ode/>
            </contact>
            <bounce/>
            <friction>
              <torsional>
                <ode/>
              </torsional>
              <ode/>
            </friction>
          </surface>
        </collision>
        <visual name='frame'>
          <geometry>
            <mesh>
              <uri>model://stop_light/meshes/stop_light.obj</uri>
              <scale>0.01 0.01 0.01</scale>
            </mesh>
          </geometry>
        </visual>
        <visual name='red'>
          <pose frame=''>-0.001123 -0.082251 -0.147514 0 -0 0</pose>
          <geometry>
            <sphere>
              <radius>0.1012</radius>
            </sphere>
          </geometry>
          <material>
            <script>
              <uri>model://stop_light/materials/scripts/</uri>
              <uri>model://stop_light/materials/textures/</uri>
              <name>StopLight/Light</name>
            </script>
            <ambient>1 0 0 1</ambient>
            <specular>1 0 0 1</specular>
          </material>
        </visual>
        <visual name='yellow'>
          <pose frame=''>-0.001123 -0.082251 -0.402 0 -0 0</pose>
          <geometry>
            <sphere>
              <radius>0.1012</radius>
            </sphere>
          </geometry>
          <material>
            <script>
              <uri>model://stop_light/materials/scripts/</uri>
              <uri>model://stop_light/materials/textures/</uri>
              <name>StopLight/Light</name>
            </script>
            <ambient>1 1 0 1</ambient>
            <specular>1 1 0 1</specular>
          </material>
        </visual>
        <visual name='green'>
          <pose frame=''>-0.001123 -0.082251 -0.655 0 -0 0</pose>
          <geometry>
            <sphere>
              <radius>0.1012</radius>
            </sphere>
          </geometry>
          <material>
            <script>
              <uri>model://stop_light/materials/scripts/</uri>
              <uri>model://stop_light/materials/textures/</uri>
              <name>StopLight/Light</name>
            </script>
            <ambient>0 1 0 1</ambient>
            <specular>0 1 0 1</specular>
          </material>
        </visual>
        <pose frame=''>-2 0.04 5.82 0 -0 0</pose>
        <self_collide>0</self_collide>
        <enable_wind>0</enable_wind>
        <kinematic>0</kinematic>
      </link>
      <pose frame=''>55.6826 -4.93829 0 0 -0 0</pose>
    </model>
    <model name='radio_tower'>
      <static>1</static>
      <link name='link'>
        <collision name='collision'>
          <geometry>
            <mesh>
              <uri>model://radio_tower/meshes/radio_tower.dae</uri>
            </mesh>
          </geometry>
          <max_contacts>10</max_contacts>
          <surface>
            <contact>
              <ode/>
            </contact>
            <bounce/>
            <friction>
              <torsional>
                <ode/>
              </torsional>
              <ode/>
            </friction>
          </surface>
        </collision>
        <visual name='visual'>
          <geometry>
            <mesh>
              <uri>model://radio_tower/meshes/radio_tower.dae</uri>
            </mesh>
          </geometry>
        </visual>
        <self_collide>0</self_collide>
        <enable_wind>0</enable_wind>
        <kinematic>0</kinematic>
      </link>
      <pose frame=''>1 0.436284 0 0 -0 0</pose>
    </model>
    <model name='Stop Sign'>
      <static>1</static>
      <link name='link'>
        <collision name='collision'>
          <geometry>
            <mesh>
              <uri>model://stop_sign/meshes/stop_sign.dae</uri>
            </mesh>
          </geometry>
          <max_contacts>10</max_contacts>
          <surface>
            <contact>
              <ode/>
            </contact>
            <bounce/>
            <friction>
              <torsional>
                <ode/>
              </torsional>
              <ode/>
            </friction>
          </surface>
        </collision>
        <visual name='visual'>
          <geometry>
            <mesh>
              <uri>model://stop_sign/meshes/stop_sign.dae</uri>
            </mesh>
          </geometry>
          <material>
            <script>
              <uri>model://stop_sign/materials/scripts</uri>
              <uri>model://stop_sign/materials/textures</uri>
              <name>StopSign/Diffuse</name>
            </script>
          </material>
        </visual>
        <self_collide>0</self_collide>
        <enable_wind>0</enable_wind>
        <kinematic>0</kinematic>
      </link>
      <pose frame=''>94.2217 -5.20314 0 0 -0 0</pose>
    </model>
    <model name='Stop Sign_0'>
      <static>1</static>
      <link name='link'>
        <collision name='collision'>
          <geometry>
            <mesh>
              <uri>model://stop_sign/meshes/stop_sign.dae</uri>
            </mesh>
          </geometry>
          <max_contacts>10</max_contacts>
          <surface>
            <contact>
              <ode/>
            </contact>
            <bounce/>
            <friction>
              <torsional>
                <ode/>
              </torsional>
              <ode/>
            </friction>
          </surface>
        </collision>
        <visual name='visual'>
          <geometry>
            <mesh>
              <uri>model://stop_sign/meshes/stop_sign.dae</uri>
            </mesh>
          </geometry>
          <material>
            <script>
              <uri>model://stop_sign/materials/scripts</uri>
              <uri>model://stop_sign/materials/textures</uri>
              <name>StopSign/Diffuse</name>
            </script>
          </material>
        </visual>
        <self_collide>0</self_collide>
        <enable_wind>0</enable_wind>
        <kinematic>0</kinematic>
      </link>
      <pose frame=''>-94.095 4.72945 0 0 -0 0</pose>
    </model>
    <model name='prius_hybrid'>
      <pose frame=''>-53.5774 72.7994 0.03 0 -0 0</pose>
      <link name='chassis'>
        <inertial>
          <mass>1326</mass>
          <pose frame=''>0 -0.266 0.48 0 -0 0</pose>
          <inertia>
            <ixx>2581.13</ixx>
            <ixy>0</ixy>
            <iyy>591.308</iyy>
            <ixz>0</ixz>
            <iyz>0</iyz>
            <izz>2681.95</izz>
          </inertia>
        </inertial>
        <visual name='chassis_visual'>
          <geometry>
            <mesh>
              <uri>model://prius_hybrid/meshes/Hybrid.obj</uri>
              <scale>0.01 0.01 0.01</scale>
              <submesh>
                <name>Hybrid</name>
                <center>0</center>
              </submesh>
            </mesh>
          </geometry>
        </visual>
        <visual name='interior_visual'>
          <geometry>
            <mesh>
              <uri>model://prius_hybrid/meshes/Hybrid.obj</uri>
              <scale>0.01 0.01 0.01</scale>
              <submesh>
                <name>Hybrid_Interior</name>
                <center>0</center>
              </submesh>
            </mesh>
          </geometry>
        </visual>
        <visual name='windows_visual'>
          <geometry>
            <mesh>
              <uri>model://prius_hybrid/meshes/Hybrid.obj</uri>
              <scale>0.01 0.01 0.01</scale>
              <submesh>
                <name>Hybrid_Windows</name>
                <center>0</center>
              </submesh>
            </mesh>
          </geometry>
        </visual>
        <collision name='chassis'>
          <pose frame=''>0 0.05 0.625 0 -0 0</pose>
          <geometry>
            <box>
              <size>1.7526 2.1 0.95</size>
            </box>
          </geometry>
          <max_contacts>10</max_contacts>
          <surface>
            <contact>
              <ode/>
            </contact>
            <bounce/>
            <friction>
              <torsional>
                <ode/>
              </torsional>
              <ode/>
            </friction>
          </surface>
        </collision>
        <collision name='front_bumper'>
          <pose frame=''>0 -2 0.458488 0 -0 0</pose>
          <geometry>
            <box>
              <size>1.33728 0.48 0.566691</size>
            </box>
          </geometry>
          <max_contacts>10</max_contacts>
          <surface>
            <contact>
              <ode/>
            </contact>
            <bounce/>
            <friction>
              <torsional>
                <ode/>
              </torsional>
              <ode/>
            </friction>
          </surface>
        </collision>
        <collision name='hood'>
          <pose frame=''>0 -1.90084 0.676305 0.341247 -0 0</pose>
          <geometry>
            <box>
              <size>1.59797 0.493107 0.265468</size>
            </box>
          </geometry>
          <max_contacts>10</max_contacts>
          <surface>
            <contact>
              <ode/>
            </contact>
            <bounce/>
            <friction>
              <torsional>
                <ode/>
              </torsional>
              <ode/>
            </friction>
          </surface>
        </collision>
        <collision name='windshield'>
          <pose frame=''>0 -0.875105 1.03227 0.335476 -0 0</pose>
          <geometry>
            <box>
              <size>1.16838 1.65425 0.272347</size>
            </box>
          </geometry>
          <max_contacts>10</max_contacts>
          <surface>
            <contact>
              <ode/>
            </contact>
            <bounce/>
            <friction>
              <torsional>
                <ode/>
              </torsional>
              <ode/>
            </friction>
          </surface>
        </collision>
        <collision name='top_front'>
          <pose frame=''>0 0.161236 1.38604 0.13503 -0 0</pose>
          <geometry>
            <box>
              <size>1.27915 0.625988 0.171868</size>
            </box>
          </geometry>
          <max_contacts>10</max_contacts>
          <surface>
            <contact>
              <ode/>
            </contact>
            <bounce/>
            <friction>
              <torsional>
                <ode/>
              </torsional>
              <ode/>
            </friction>
          </surface>
        </collision>
        <collision name='top_rear'>
          <pose frame=''>0 0.817696 1.36007 -0.068997 0 0</pose>
          <geometry>
            <box>
              <size>1.28513 0.771189 0.226557</size>
            </box>
          </geometry>
          <max_contacts>10</max_contacts>
          <surface>
            <contact>
              <ode/>
            </contact>
            <bounce/>
            <friction>
              <torsional>
                <ode/>
              </torsional>
              <ode/>
            </friction>
          </surface>
        </collision>
        <collision name='rear_window'>
          <pose frame=''>0 1.64053 1.17513 -0.262017 0 0</pose>
          <geometry>
            <box>
              <size>1.26785 1.11634 0.244286</size>
            </box>
          </geometry>
          <max_contacts>10</max_contacts>
          <surface>
            <contact>
              <ode/>
            </contact>
            <bounce/>
            <friction>
              <torsional>
                <ode/>
              </torsional>
              <ode/>
            </friction>
          </surface>
        </collision>
        <collision name='trunk'>
          <pose frame=''>0 1.63706 0.88818 0 -0 0</pose>
          <geometry>
            <box>
              <size>1.78806 1.13899 0.482746</size>
            </box>
          </geometry>
          <max_contacts>10</max_contacts>
          <surface>
            <contact>
              <ode/>
            </contact>
            <bounce/>
            <friction>
              <torsional>
                <ode/>
              </torsional>
              <ode/>
            </friction>
          </surface>
        </collision>
        <collision name='back_bumper'>
          <pose frame=''>0 2.05445 0.57787 0 -0 0</pose>
          <geometry>
            <box>
              <size>1.78165 0.512093 0.581427</size>
            </box>
          </geometry>
          <max_contacts>10</max_contacts>
          <surface>
            <contact>
              <ode/>
            </contact>
            <bounce/>
            <friction>
              <torsional>
                <ode/>
              </torsional>
              <ode/>
            </friction>
          </surface>
        </collision>
        <self_collide>0</self_collide>
        <enable_wind>0</enable_wind>
        <kinematic>0</kinematic>
      </link>
      <link name='steering_wheel'>
        <pose frame=''>0.357734 -0.627868 0.988243 -1.3021 0 0</pose>
        <inertial>
          <mass>1</mass>
          <inertia>
            <ixx>0.145833</ixx>
            <ixy>0</ixy>
            <ixz>0</ixz>
            <iyy>0.145833</iyy>
            <iyz>0</iyz>
            <izz>0.125</izz>
          </inertia>
        </inertial>
        <collision name='collision'>
          <geometry>
            <cylinder>
              <radius>0.178172</radius>
              <length>0.041845</length>
            </cylinder>
          </geometry>
          <surface>
            <contact>
              <ode>
                <min_depth>0.003</min_depth>
              </ode>
            </contact>
            <bounce/>
            <friction>
              <torsional>
                <ode/>
              </torsional>
              <ode/>
            </friction>
          </surface>
          <max_contacts>10</max_contacts>
        </collision>
        <visual name='visual'>
          <pose frame=''>0 0 0 1.3021 -0 0</pose>
          <geometry>
            <mesh>
              <uri>model://prius_hybrid/meshes/Hybrid.obj</uri>
              <scale>0.01 0.01 0.01</scale>
              <submesh>
                <name>Steering_Wheel</name>
                <center>1</center>
              </submesh>
            </mesh>
          </geometry>
        </visual>
        <self_collide>0</self_collide>
        <enable_wind>0</enable_wind>
        <kinematic>0</kinematic>
      </link>
      <link name='front_left_wheel'>
        <pose frame=''>0.76 -1.41 0.3 0 -0 0</pose>
        <inertial>
          <mass>11</mass>
          <inertia>
            <ixx>0.586312</ixx>
            <ixy>0</ixy>
            <iyy>0.335529</iyy>
            <ixz>0</ixz>
            <iyz>0</iyz>
            <izz>0.335529</izz>
          </inertia>
        </inertial>
        <visual name='visual'>
          <pose frame=''>0.04 0 0 0 -0 0</pose>
          <geometry>
            <mesh>
              <uri>model://prius_hybrid/meshes/Hybrid.obj</uri>
              <scale>0.01 0.01 0.01</scale>
              <submesh>
                <name>Wheel_Front_Left_</name>
                <center>1</center>
              </submesh>
            </mesh>
          </geometry>
        </visual>
        <collision name='collision'>
          <pose frame=''>0 0 0 3.14159 1.57079 3.14159</pose>
          <geometry>
            <sphere>
              <radius>0.31265</radius>
            </sphere>
          </geometry>
          <surface>
            <friction>
              <ode>
                <mu>0.9</mu>
                <mu2>0.9</mu2>
                <slip1>0</slip1>
                <slip2>0</slip2>
              </ode>
              <torsional>
                <ode/>
              </torsional>
            </friction>
            <contact>
              <ode>
                <min_depth>0.001</min_depth>
                <kp>1e+09</kp>
              </ode>
            </contact>
            <bounce/>
          </surface>
          <max_contacts>10</max_contacts>
        </collision>
        <self_collide>0</self_collide>
        <enable_wind>0</enable_wind>
        <kinematic>0</kinematic>
      </link>
      <link name='front_right_wheel'>
        <pose frame=''>-0.76 -1.41 0.3 0 -0 0</pose>
        <inertial>
          <mass>11</mass>
          <inertia>
            <ixx>0.586312</ixx>
            <ixy>0</ixy>
            <iyy>0.335529</iyy>
            <ixz>0</ixz>
            <iyz>0</iyz>
            <izz>0.335529</izz>
          </inertia>
        </inertial>
        <visual name='visual'>
          <pose frame=''>-0.04 0 0 0 -0 0</pose>
          <pose frame=''>0 0 0 0 -0 0</pose>
          <geometry>
            <mesh>
              <uri>model://prius_hybrid/meshes/Hybrid.obj</uri>
              <scale>0.01 0.01 0.01</scale>
              <submesh>
                <name>Wheel_Front_Right</name>
                <center>1</center>
              </submesh>
            </mesh>
          </geometry>
        </visual>
        <collision name='collision'>
          <pose frame=''>0 0 0 3.14159 1.57079 3.14159</pose>
          <geometry>
            <sphere>
              <radius>0.31265</radius>
            </sphere>
          </geometry>
          <surface>
            <friction>
              <ode>
                <mu>0.9</mu>
                <mu2>0.9</mu2>
                <slip1>0</slip1>
                <slip2>0</slip2>
              </ode>
              <torsional>
                <ode/>
              </torsional>
            </friction>
            <contact>
              <ode>
                <min_depth>0.001</min_depth>
                <kp>1e+09</kp>
              </ode>
            </contact>
            <bounce/>
          </surface>
          <max_contacts>10</max_contacts>
        </collision>
        <self_collide>0</self_collide>
        <enable_wind>0</enable_wind>
        <kinematic>0</kinematic>
      </link>
      <link name='rear_left_wheel'>
        <pose frame=''>0.786 1.45 0.3 0 -0 0</pose>
        <inertial>
          <mass>11</mass>
          <inertia>
            <ixx>0.586312</ixx>
            <ixy>0</ixy>
            <iyy>0.335529</iyy>
            <ixz>0</ixz>
            <iyz>0</iyz>
            <izz>0.335529</izz>
          </inertia>
        </inertial>
        <visual name='visual'>
          <pose frame=''>0.04 0 0 0 -0 0</pose>
          <geometry>
            <mesh>
              <uri>model://prius_hybrid/meshes/Hybrid.obj</uri>
              <scale>0.01 0.01 0.01</scale>
              <submesh>
                <name>Wheel_Front_Left_</name>
                <center>1</center>
              </submesh>
            </mesh>
          </geometry>
        </visual>
        <collision name='collision'>
          <pose frame=''>0 0 0 3.14159 1.57079 3.14159</pose>
          <geometry>
            <sphere>
              <radius>0.31265</radius>
            </sphere>
          </geometry>
          <surface>
            <friction>
              <ode>
                <mu>1.1</mu>
                <mu2>1.1</mu2>
                <slip1>0</slip1>
                <slip2>0</slip2>
              </ode>
              <torsional>
                <ode/>
              </torsional>
            </friction>
            <contact>
              <ode>
                <min_depth>0.001</min_depth>
                <kp>1e+09</kp>
              </ode>
            </contact>
            <bounce/>
          </surface>
          <max_contacts>10</max_contacts>
        </collision>
        <self_collide>0</self_collide>
        <enable_wind>0</enable_wind>
        <kinematic>0</kinematic>
      </link>
      <link name='rear_right_wheel'>
        <pose frame=''>-0.786 1.45 0.3 0 -0 0</pose>
        <inertial>
          <mass>11</mass>
          <inertia>
            <ixx>0.586312</ixx>
            <ixy>0</ixy>
            <iyy>0.335529</iyy>
            <ixz>0</ixz>
            <iyz>0</iyz>
            <izz>0.335529</izz>
          </inertia>
        </inertial>
        <visual name='visual'>
          <pose frame=''>-0.04 0 0 0 -0 0</pose>
          <geometry>
            <mesh>
              <uri>model://prius_hybrid/meshes/Hybrid.obj</uri>
              <scale>0.01 0.01 0.01</scale>
              <submesh>
                <name>Wheel_Front_Right</name>
                <center>1</center>
              </submesh>
            </mesh>
          </geometry>
        </visual>
        <collision name='collision'>
          <pose frame=''>0 0 0 3.14159 1.57079 3.14159</pose>
          <geometry>
            <sphere>
              <radius>0.31265</radius>
            </sphere>
          </geometry>
          <surface>
            <friction>
              <ode>
                <mu>1.1</mu>
                <mu2>1.1</mu2>
                <slip1>0</slip1>
                <slip2>0</slip2>
              </ode>
              <torsional>
                <ode/>
              </torsional>
            </friction>
            <contact>
              <ode>
                <min_depth>0.001</min_depth>
                <kp>1e+09</kp>
              </ode>
            </contact>
            <bounce/>
          </surface>
          <max_contacts>10</max_contacts>
        </collision>
        <self_collide>0</self_collide>
        <enable_wind>0</enable_wind>
        <kinematic>0</kinematic>
      </link>
      <joint name='front_left_combined_joint' type='universal'>
        <pose frame=''>0 0 0 -0.087266 0 0</pose>
        <child>front_left_wheel</child>
        <parent>chassis</parent>
        <axis>
          <xyz>0 0 1</xyz>
          <limit>
            <lower>-0.8727</lower>
            <upper>0.8727</upper>
          </limit>
          <use_parent_model_frame>0</use_parent_model_frame>
          <dynamics>
            <spring_reference>0</spring_reference>
            <spring_stiffness>0</spring_stiffness>
          </dynamics>
        </axis>
        <axis2>
          <xyz>1 0 0</xyz>
          <dynamics>
            <friction>18.0474</friction>
            <spring_reference>0</spring_reference>
            <spring_stiffness>0</spring_stiffness>
          </dynamics>
          <use_parent_model_frame>0</use_parent_model_frame>
        </axis2>
      </joint>
      <joint name='front_right_combined_joint' type='universal'>
        <pose frame=''>0 0 0 -0.087266 0 0</pose>
        <child>front_right_wheel</child>
        <parent>chassis</parent>
        <axis>
          <xyz>0 0 1</xyz>
          <limit>
            <lower>-0.8727</lower>
            <upper>0.8727</upper>
          </limit>
          <use_parent_model_frame>0</use_parent_model_frame>
          <dynamics>
            <spring_reference>0</spring_reference>
            <spring_stiffness>0</spring_stiffness>
          </dynamics>
        </axis>
        <axis2>
          <xyz>1 0 0</xyz>
          <dynamics>
            <friction>18.0474</friction>
            <spring_reference>0</spring_reference>
            <spring_stiffness>0</spring_stiffness>
          </dynamics>
          <use_parent_model_frame>0</use_parent_model_frame>
        </axis2>
      </joint>
      <link name='rear_axle'>
        <pose frame=''>0 1.45 0.3 0 -0 0</pose>
        <inertial>
          <mass>30</mass>
          <inertia>
            <ixx>0.084375</ixx>
            <ixy>0</ixy>
            <iyy>4.64581</iyy>
            <ixz>0</ixz>
            <iyz>0</iyz>
            <izz>4.64581</izz>
          </inertia>
        </inertial>
        <visual name='visual'>
          <pose frame=''>0 0 0 3.14159 1.57079 3.14159</pose>
          <geometry>
            <cylinder>
              <length>1.357</length>
              <radius>0.075</radius>
            </cylinder>
          </geometry>
          <material>
            <script>
              <name>Gazebo/Grey</name>
              <uri>file://media/materials/scripts/gazebo.material</uri>
            </script>
          </material>
        </visual>
        <self_collide>0</self_collide>
        <enable_wind>0</enable_wind>
        <kinematic>0</kinematic>
      </link>
      <joint name='rear_axle_joint' type='revolute'>
        <child>rear_axle</child>
        <parent>chassis</parent>
        <axis>
          <xyz>0 1 0</xyz>
          <limit>
            <lower>-0.0508906</lower>
            <upper>0.0508906</upper>
          </limit>
          <dynamics>
            <spring_stiffness>20000</spring_stiffness>
            <damping>2000</damping>
            <spring_reference>0</spring_reference>
          </dynamics>
          <use_parent_model_frame>0</use_parent_model_frame>
        </axis>
      </joint>
      <joint name='rear_left_wheel_joint' type='revolute'>
        <child>rear_left_wheel</child>
        <parent>rear_axle</parent>
        <axis>
          <xyz>1 0 0</xyz>
          <dynamics>
            <friction>12.0316</friction>
            <spring_reference>0</spring_reference>
            <spring_stiffness>0</spring_stiffness>
          </dynamics>
          <use_parent_model_frame>0</use_parent_model_frame>
          <limit>
            <lower>-1e+16</lower>
            <upper>1e+16</upper>
          </limit>
        </axis>
      </joint>
      <joint name='rear_right_wheel_joint' type='revolute'>
        <child>rear_right_wheel</child>
        <parent>rear_axle</parent>
        <axis>
          <xyz>1 0 0</xyz>
          <dynamics>
            <friction>12.0316</friction>
            <spring_reference>0</spring_reference>
            <spring_stiffness>0</spring_stiffness>
          </dynamics>
          <use_parent_model_frame>0</use_parent_model_frame>
          <limit>
            <lower>-1e+16</lower>
            <upper>1e+16</upper>
          </limit>
        </axis>
      </joint>
      <joint name='steering_joint' type='revolute'>
        <pose frame=''>-0.002 0 0 0 -0 0</pose>
        <parent>chassis</parent>
        <child>steering_wheel</child>
        <axis>
          <xyz>0 0.964095 0.265556</xyz>
          <limit>
            <lower>-7.85</lower>
            <upper>7.85</upper>
          </limit>
          <dynamics>
            <damping>1</damping>
            <spring_reference>0</spring_reference>
            <spring_stiffness>0</spring_stiffness>
          </dynamics>
          <use_parent_model_frame>1</use_parent_model_frame>
        </axis>
        <physics>
          <ode>
            <cfm_damping>1</cfm_damping>
            <limit>
              <cfm>0</cfm>
              <erp>0.2</erp>
            </limit>
          </ode>
        </physics>
      </joint>
    </model>
    <model name='bus'>
      <static>1</static>
      <link name='link'>
        <collision name='collision'>
          <geometry>
            <mesh>
              <scale>0.01 0.01 0.01</scale>
              <uri>model://bus/meshes/bus.obj</uri>
            </mesh>
          </geometry>
          <max_contacts>10</max_contacts>
          <surface>
            <contact>
              <ode/>
            </contact>
            <bounce/>
            <friction>
              <torsional>
                <ode/>
              </torsional>
              <ode/>
            </friction>
          </surface>
        </collision>
        <visual name='visual'>
          <geometry>
            <mesh>
              <scale>0.01 0.01 0.01</scale>
              <uri>model://bus/meshes/bus.obj</uri>
            </mesh>
          </geometry>
        </visual>
        <self_collide>0</self_collide>
        <enable_wind>0</enable_wind>
        <kinematic>0</kinematic>
      </link>
      <pose frame=''>44.2185 54.4063 0 0 -0 0</pose>
    </model>
    <model name='ambulance'>
      <static>1</static>
      <link name='link'>
        <collision name='collision'>
          <geometry>
            <mesh>
              <scale>0.0254 0.0254 0.0254</scale>
              <uri>model://ambulance/meshes/ambulance.obj</uri>
            </mesh>
          </geometry>
          <max_contacts>10</max_contacts>
          <surface>
            <contact>
              <ode/>
            </contact>
            <bounce/>
            <friction>
              <torsional>
                <ode/>
              </torsional>
              <ode/>
            </friction>
          </surface>
        </collision>
        <visual name='visual'>
          <geometry>
            <mesh>
              <scale>0.0254 0.0254 0.0254</scale>
              <uri>model://ambulance/meshes/ambulance.obj</uri>
            </mesh>
          </geometry>
        </visual>
        <self_collide>0</self_collide>
        <enable_wind>0</enable_wind>
        <kinematic>0</kinematic>
      </link>
      <pose frame=''>-49.5471 44.0018 0 0 -0 0</pose>
    </model>
    <model name='prius_hybrid_0'>
      <pose frame=''>49.7586 59.2402 0.03 0 -0 0</pose>
      <link name='chassis'>
        <inertial>
          <mass>1326</mass>
          <pose frame=''>0 -0.266 0.48 0 -0 0</pose>
          <inertia>
            <ixx>2581.13</ixx>
            <ixy>0</ixy>
            <iyy>591.308</iyy>
            <ixz>0</ixz>
            <iyz>0</iyz>
            <izz>2681.95</izz>
          </inertia>
        </inertial>
        <visual name='chassis_visual'>
          <geometry>
            <mesh>
              <uri>model://prius_hybrid/meshes/Hybrid.obj</uri>
              <scale>0.01 0.01 0.01</scale>
              <submesh>
                <name>Hybrid</name>
                <center>0</center>
              </submesh>
            </mesh>
          </geometry>
        </visual>
        <visual name='interior_visual'>
          <geometry>
            <mesh>
              <uri>model://prius_hybrid/meshes/Hybrid.obj</uri>
              <scale>0.01 0.01 0.01</scale>
              <submesh>
                <name>Hybrid_Interior</name>
                <center>0</center>
              </submesh>
            </mesh>
          </geometry>
        </visual>
        <visual name='windows_visual'>
          <geometry>
            <mesh>
              <uri>model://prius_hybrid/meshes/Hybrid.obj</uri>
              <scale>0.01 0.01 0.01</scale>
              <submesh>
                <name>Hybrid_Windows</name>
                <center>0</center>
              </submesh>
            </mesh>
          </geometry>
        </visual>
        <collision name='chassis'>
          <pose frame=''>0 0.05 0.625 0 -0 0</pose>
          <geometry>
            <box>
              <size>1.7526 2.1 0.95</size>
            </box>
          </geometry>
          <max_contacts>10</max_contacts>
          <surface>
            <contact>
              <ode/>
            </contact>
            <bounce/>
            <friction>
              <torsional>
                <ode/>
              </torsional>
              <ode/>
            </friction>
          </surface>
        </collision>
        <collision name='front_bumper'>
          <pose frame=''>0 -2 0.458488 0 -0 0</pose>
          <geometry>
            <box>
              <size>1.33728 0.48 0.566691</size>
            </box>
          </geometry>
          <max_contacts>10</max_contacts>
          <surface>
            <contact>
              <ode/>
            </contact>
            <bounce/>
            <friction>
              <torsional>
                <ode/>
              </torsional>
              <ode/>
            </friction>
          </surface>
        </collision>
        <collision name='hood'>
          <pose frame=''>0 -1.90084 0.676305 0.341247 -0 0</pose>
          <geometry>
            <box>
              <size>1.59797 0.493107 0.265468</size>
            </box>
          </geometry>
          <max_contacts>10</max_contacts>
          <surface>
            <contact>
              <ode/>
            </contact>
            <bounce/>
            <friction>
              <torsional>
                <ode/>
              </torsional>
              <ode/>
            </friction>
          </surface>
        </collision>
        <collision name='windshield'>
          <pose frame=''>0 -0.875105 1.03227 0.335476 -0 0</pose>
          <geometry>
            <box>
              <size>1.16838 1.65425 0.272347</size>
            </box>
          </geometry>
          <max_contacts>10</max_contacts>
          <surface>
            <contact>
              <ode/>
            </contact>
            <bounce/>
            <friction>
              <torsional>
                <ode/>
              </torsional>
              <ode/>
            </friction>
          </surface>
        </collision>
        <collision name='top_front'>
          <pose frame=''>0 0.161236 1.38604 0.13503 -0 0</pose>
          <geometry>
            <box>
              <size>1.27915 0.625988 0.171868</size>
            </box>
          </geometry>
          <max_contacts>10</max_contacts>
          <surface>
            <contact>
              <ode/>
            </contact>
            <bounce/>
            <friction>
              <torsional>
                <ode/>
              </torsional>
              <ode/>
            </friction>
          </surface>
        </collision>
        <collision name='top_rear'>
          <pose frame=''>0 0.817696 1.36007 -0.068997 0 0</pose>
          <geometry>
            <box>
              <size>1.28513 0.771189 0.226557</size>
            </box>
          </geometry>
          <max_contacts>10</max_contacts>
          <surface>
            <contact>
              <ode/>
            </contact>
            <bounce/>
            <friction>
              <torsional>
                <ode/>
              </torsional>
              <ode/>
            </friction>
          </surface>
        </collision>
        <collision name='rear_window'>
          <pose frame=''>0 1.64053 1.17513 -0.262017 0 0</pose>
          <geometry>
            <box>
              <size>1.26785 1.11634 0.244286</size>
            </box>
          </geometry>
          <max_contacts>10</max_contacts>
          <surface>
            <contact>
              <ode/>
            </contact>
            <bounce/>
            <friction>
              <torsional>
                <ode/>
              </torsional>
              <ode/>
            </friction>
          </surface>
        </collision>
        <collision name='trunk'>
          <pose frame=''>0 1.63706 0.88818 0 -0 0</pose>
          <geometry>
            <box>
              <size>1.78806 1.13899 0.482746</size>
            </box>
          </geometry>
          <max_contacts>10</max_contacts>
          <surface>
            <contact>
              <ode/>
            </contact>
            <bounce/>
            <friction>
              <torsional>
                <ode/>
              </torsional>
              <ode/>
            </friction>
          </surface>
        </collision>
        <collision name='back_bumper'>
          <pose frame=''>0 2.05445 0.57787 0 -0 0</pose>
          <geometry>
            <box>
              <size>1.78165 0.512093 0.581427</size>
            </box>
          </geometry>
          <max_contacts>10</max_contacts>
          <surface>
            <contact>
              <ode/>
            </contact>
            <bounce/>
            <friction>
              <torsional>
                <ode/>
              </torsional>
              <ode/>
            </friction>
          </surface>
        </collision>
        <self_collide>0</self_collide>
        <enable_wind>0</enable_wind>
        <kinematic>0</kinematic>
      </link>
      <link name='steering_wheel'>
        <pose frame=''>0.357734 -0.627868 0.988243 -1.3021 0 0</pose>
        <inertial>
          <mass>1</mass>
          <inertia>
            <ixx>0.145833</ixx>
            <ixy>0</ixy>
            <ixz>0</ixz>
            <iyy>0.145833</iyy>
            <iyz>0</iyz>
            <izz>0.125</izz>
          </inertia>
        </inertial>
        <collision name='collision'>
          <geometry>
            <cylinder>
              <radius>0.178172</radius>
              <length>0.041845</length>
            </cylinder>
          </geometry>
          <surface>
            <contact>
              <ode>
                <min_depth>0.003</min_depth>
              </ode>
            </contact>
            <bounce/>
            <friction>
              <torsional>
                <ode/>
              </torsional>
              <ode/>
            </friction>
          </surface>
          <max_contacts>10</max_contacts>
        </collision>
        <visual name='visual'>
          <pose frame=''>0 0 0 1.3021 -0 0</pose>
          <geometry>
            <mesh>
              <uri>model://prius_hybrid/meshes/Hybrid.obj</uri>
              <scale>0.01 0.01 0.01</scale>
              <submesh>
                <name>Steering_Wheel</name>
                <center>1</center>
              </submesh>
            </mesh>
          </geometry>
        </visual>
        <self_collide>0</self_collide>
        <enable_wind>0</enable_wind>
        <kinematic>0</kinematic>
      </link>
      <link name='front_left_wheel'>
        <pose frame=''>0.76 -1.41 0.3 0 -0 0</pose>
        <inertial>
          <mass>11</mass>
          <inertia>
            <ixx>0.586312</ixx>
            <ixy>0</ixy>
            <iyy>0.335529</iyy>
            <ixz>0</ixz>
            <iyz>0</iyz>
            <izz>0.335529</izz>
          </inertia>
        </inertial>
        <visual name='visual'>
          <pose frame=''>0.04 0 0 0 -0 0</pose>
          <geometry>
            <mesh>
              <uri>model://prius_hybrid/meshes/Hybrid.obj</uri>
              <scale>0.01 0.01 0.01</scale>
              <submesh>
                <name>Wheel_Front_Left_</name>
                <center>1</center>
              </submesh>
            </mesh>
          </geometry>
        </visual>
        <collision name='collision'>
          <pose frame=''>0 0 0 3.14159 1.57079 3.14159</pose>
          <geometry>
            <sphere>
              <radius>0.31265</radius>
            </sphere>
          </geometry>
          <surface>
            <friction>
              <ode>
                <mu>0.9</mu>
                <mu2>0.9</mu2>
                <slip1>0</slip1>
                <slip2>0</slip2>
              </ode>
              <torsional>
                <ode/>
              </torsional>
            </friction>
            <contact>
              <ode>
                <min_depth>0.001</min_depth>
                <kp>1e+09</kp>
              </ode>
            </contact>
            <bounce/>
          </surface>
          <max_contacts>10</max_contacts>
        </collision>
        <self_collide>0</self_collide>
        <enable_wind>0</enable_wind>
        <kinematic>0</kinematic>
      </link>
      <link name='front_right_wheel'>
        <pose frame=''>-0.76 -1.41 0.3 0 -0 0</pose>
        <inertial>
          <mass>11</mass>
          <inertia>
            <ixx>0.586312</ixx>
            <ixy>0</ixy>
            <iyy>0.335529</iyy>
            <ixz>0</ixz>
            <iyz>0</iyz>
            <izz>0.335529</izz>
          </inertia>
        </inertial>
        <visual name='visual'>
          <pose frame=''>-0.04 0 0 0 -0 0</pose>
          <pose frame=''>0 0 0 0 -0 0</pose>
          <geometry>
            <mesh>
              <uri>model://prius_hybrid/meshes/Hybrid.obj</uri>
              <scale>0.01 0.01 0.01</scale>
              <submesh>
                <name>Wheel_Front_Right</name>
                <center>1</center>
              </submesh>
            </mesh>
          </geometry>
        </visual>
        <collision name='collision'>
          <pose frame=''>0 0 0 3.14159 1.57079 3.14159</pose>
          <geometry>
            <sphere>
              <radius>0.31265</radius>
            </sphere>
          </geometry>
          <surface>
            <friction>
              <ode>
                <mu>0.9</mu>
                <mu2>0.9</mu2>
                <slip1>0</slip1>
                <slip2>0</slip2>
              </ode>
              <torsional>
                <ode/>
              </torsional>
            </friction>
            <contact>
              <ode>
                <min_depth>0.001</min_depth>
                <kp>1e+09</kp>
              </ode>
            </contact>
            <bounce/>
          </surface>
          <max_contacts>10</max_contacts>
        </collision>
        <self_collide>0</self_collide>
        <enable_wind>0</enable_wind>
        <kinematic>0</kinematic>
      </link>
      <link name='rear_left_wheel'>
        <pose frame=''>0.786 1.45 0.3 0 -0 0</pose>
        <inertial>
          <mass>11</mass>
          <inertia>
            <ixx>0.586312</ixx>
            <ixy>0</ixy>
            <iyy>0.335529</iyy>
            <ixz>0</ixz>
            <iyz>0</iyz>
            <izz>0.335529</izz>
          </inertia>
        </inertial>
        <visual name='visual'>
          <pose frame=''>0.04 0 0 0 -0 0</pose>
          <geometry>
            <mesh>
              <uri>model://prius_hybrid/meshes/Hybrid.obj</uri>
              <scale>0.01 0.01 0.01</scale>
              <submesh>
                <name>Wheel_Front_Left_</name>
                <center>1</center>
              </submesh>
            </mesh>
          </geometry>
        </visual>
        <collision name='collision'>
          <pose frame=''>0 0 0 3.14159 1.57079 3.14159</pose>
          <geometry>
            <sphere>
              <radius>0.31265</radius>
            </sphere>
          </geometry>
          <surface>
            <friction>
              <ode>
                <mu>1.1</mu>
                <mu2>1.1</mu2>
                <slip1>0</slip1>
                <slip2>0</slip2>
              </ode>
              <torsional>
                <ode/>
              </torsional>
            </friction>
            <contact>
              <ode>
                <min_depth>0.001</min_depth>
                <kp>1e+09</kp>
              </ode>
            </contact>
            <bounce/>
          </surface>
          <max_contacts>10</max_contacts>
        </collision>
        <self_collide>0</self_collide>
        <enable_wind>0</enable_wind>
        <kinematic>0</kinematic>
      </link>
      <link name='rear_right_wheel'>
        <pose frame=''>-0.786 1.45 0.3 0 -0 0</pose>
        <inertial>
          <mass>11</mass>
          <inertia>
            <ixx>0.586312</ixx>
            <ixy>0</ixy>
            <iyy>0.335529</iyy>
            <ixz>0</ixz>
            <iyz>0</iyz>
            <izz>0.335529</izz>
          </inertia>
        </inertial>
        <visual name='visual'>
          <pose frame=''>-0.04 0 0 0 -0 0</pose>
          <geometry>
            <mesh>
              <uri>model://prius_hybrid/meshes/Hybrid.obj</uri>
              <scale>0.01 0.01 0.01</scale>
              <submesh>
                <name>Wheel_Front_Right</name>
                <center>1</center>
              </submesh>
            </mesh>
          </geometry>
        </visual>
        <collision name='collision'>
          <pose frame=''>0 0 0 3.14159 1.57079 3.14159</pose>
          <geometry>
            <sphere>
              <radius>0.31265</radius>
            </sphere>
          </geometry>
          <surface>
            <friction>
              <ode>
                <mu>1.1</mu>
                <mu2>1.1</mu2>
                <slip1>0</slip1>
                <slip2>0</slip2>
              </ode>
              <torsional>
                <ode/>
              </torsional>
            </friction>
            <contact>
              <ode>
                <min_depth>0.001</min_depth>
                <kp>1e+09</kp>
              </ode>
            </contact>
            <bounce/>
          </surface>
          <max_contacts>10</max_contacts>
        </collision>
        <self_collide>0</self_collide>
        <enable_wind>0</enable_wind>
        <kinematic>0</kinematic>
      </link>
      <joint name='front_left_combined_joint' type='universal'>
        <pose frame=''>0 0 0 -0.087266 0 0</pose>
        <child>front_left_wheel</child>
        <parent>chassis</parent>
        <axis>
          <xyz>0 0 1</xyz>
          <limit>
            <lower>-0.8727</lower>
            <upper>0.8727</upper>
          </limit>
          <use_parent_model_frame>0</use_parent_model_frame>
          <dynamics>
            <spring_reference>0</spring_reference>
            <spring_stiffness>0</spring_stiffness>
          </dynamics>
        </axis>
        <axis2>
          <xyz>1 0 0</xyz>
          <dynamics>
            <friction>18.0474</friction>
            <spring_reference>0</spring_reference>
            <spring_stiffness>0</spring_stiffness>
          </dynamics>
          <use_parent_model_frame>0</use_parent_model_frame>
        </axis2>
      </joint>
      <joint name='front_right_combined_joint' type='universal'>
        <pose frame=''>0 0 0 -0.087266 0 0</pose>
        <child>front_right_wheel</child>
        <parent>chassis</parent>
        <axis>
          <xyz>0 0 1</xyz>
          <limit>
            <lower>-0.8727</lower>
            <upper>0.8727</upper>
          </limit>
          <use_parent_model_frame>0</use_parent_model_frame>
          <dynamics>
            <spring_reference>0</spring_reference>
            <spring_stiffness>0</spring_stiffness>
          </dynamics>
        </axis>
        <axis2>
          <xyz>1 0 0</xyz>
          <dynamics>
            <friction>18.0474</friction>
            <spring_reference>0</spring_reference>
            <spring_stiffness>0</spring_stiffness>
          </dynamics>
          <use_parent_model_frame>0</use_parent_model_frame>
        </axis2>
      </joint>
      <link name='rear_axle'>
        <pose frame=''>0 1.45 0.3 0 -0 0</pose>
        <inertial>
          <mass>30</mass>
          <inertia>
            <ixx>0.084375</ixx>
            <ixy>0</ixy>
            <iyy>4.64581</iyy>
            <ixz>0</ixz>
            <iyz>0</iyz>
            <izz>4.64581</izz>
          </inertia>
        </inertial>
        <visual name='visual'>
          <pose frame=''>0 0 0 3.14159 1.57079 3.14159</pose>
          <geometry>
            <cylinder>
              <length>1.357</length>
              <radius>0.075</radius>
            </cylinder>
          </geometry>
          <material>
            <script>
              <name>Gazebo/Grey</name>
              <uri>file://media/materials/scripts/gazebo.material</uri>
            </script>
          </material>
        </visual>
        <self_collide>0</self_collide>
        <enable_wind>0</enable_wind>
        <kinematic>0</kinematic>
      </link>
      <joint name='rear_axle_joint' type='revolute'>
        <child>rear_axle</child>
        <parent>chassis</parent>
        <axis>
          <xyz>0 1 0</xyz>
          <limit>
            <lower>-0.0508906</lower>
            <upper>0.0508906</upper>
          </limit>
          <dynamics>
            <spring_stiffness>20000</spring_stiffness>
            <damping>2000</damping>
            <spring_reference>0</spring_reference>
          </dynamics>
          <use_parent_model_frame>0</use_parent_model_frame>
        </axis>
      </joint>
      <joint name='rear_left_wheel_joint' type='revolute'>
        <child>rear_left_wheel</child>
        <parent>rear_axle</parent>
        <axis>
          <xyz>1 0 0</xyz>
          <dynamics>
            <friction>12.0316</friction>
            <spring_reference>0</spring_reference>
            <spring_stiffness>0</spring_stiffness>
          </dynamics>
          <use_parent_model_frame>0</use_parent_model_frame>
          <limit>
            <lower>-1e+16</lower>
            <upper>1e+16</upper>
          </limit>
        </axis>
      </joint>
      <joint name='rear_right_wheel_joint' type='revolute'>
        <child>rear_right_wheel</child>
        <parent>rear_axle</parent>
        <axis>
          <xyz>1 0 0</xyz>
          <dynamics>
            <friction>12.0316</friction>
            <spring_reference>0</spring_reference>
            <spring_stiffness>0</spring_stiffness>
          </dynamics>
          <use_parent_model_frame>0</use_parent_model_frame>
          <limit>
            <lower>-1e+16</lower>
            <upper>1e+16</upper>
          </limit>
        </axis>
      </joint>
      <joint name='steering_joint' type='revolute'>
        <pose frame=''>-0.002 0 0 0 -0 0</pose>
        <parent>chassis</parent>
        <child>steering_wheel</child>
        <axis>
          <xyz>0 0.964095 0.265556</xyz>
          <limit>
            <lower>-7.85</lower>
            <upper>7.85</upper>
          </limit>
          <dynamics>
            <damping>1</damping>
            <spring_reference>0</spring_reference>
            <spring_stiffness>0</spring_stiffness>
          </dynamics>
          <use_parent_model_frame>1</use_parent_model_frame>
        </axis>
        <physics>
          <ode>
            <cfm_damping>1</cfm_damping>
            <limit>
              <cfm>0</cfm>
              <erp>0.2</erp>
            </limit>
          </ode>
        </physics>
      </joint>
    </model>
    <model name='prius_hybrid_1'>
      <pose frame=''>38.6526 55.9495 0.03 0 -0 0</pose>
      <link name='chassis'>
        <inertial>
          <mass>1326</mass>
          <pose frame=''>0 -0.266 0.48 0 -0 0</pose>
          <inertia>
            <ixx>2581.13</ixx>
            <ixy>0</ixy>
            <iyy>591.308</iyy>
            <ixz>0</ixz>
            <iyz>0</iyz>
            <izz>2681.95</izz>
          </inertia>
        </inertial>
        <visual name='chassis_visual'>
          <geometry>
            <mesh>
              <uri>model://prius_hybrid/meshes/Hybrid.obj</uri>
              <scale>0.01 0.01 0.01</scale>
              <submesh>
                <name>Hybrid</name>
                <center>0</center>
              </submesh>
            </mesh>
          </geometry>
        </visual>
        <visual name='interior_visual'>
          <geometry>
            <mesh>
              <uri>model://prius_hybrid/meshes/Hybrid.obj</uri>
              <scale>0.01 0.01 0.01</scale>
              <submesh>
                <name>Hybrid_Interior</name>
                <center>0</center>
              </submesh>
            </mesh>
          </geometry>
        </visual>
        <visual name='windows_visual'>
          <geometry>
            <mesh>
              <uri>model://prius_hybrid/meshes/Hybrid.obj</uri>
              <scale>0.01 0.01 0.01</scale>
              <submesh>
                <name>Hybrid_Windows</name>
                <center>0</center>
              </submesh>
            </mesh>
          </geometry>
        </visual>
        <collision name='chassis'>
          <pose frame=''>0 0.05 0.625 0 -0 0</pose>
          <geometry>
            <box>
              <size>1.7526 2.1 0.95</size>
            </box>
          </geometry>
          <max_contacts>10</max_contacts>
          <surface>
            <contact>
              <ode/>
            </contact>
            <bounce/>
            <friction>
              <torsional>
                <ode/>
              </torsional>
              <ode/>
            </friction>
          </surface>
        </collision>
        <collision name='front_bumper'>
          <pose frame=''>0 -2 0.458488 0 -0 0</pose>
          <geometry>
            <box>
              <size>1.33728 0.48 0.566691</size>
            </box>
          </geometry>
          <max_contacts>10</max_contacts>
          <surface>
            <contact>
              <ode/>
            </contact>
            <bounce/>
            <friction>
              <torsional>
                <ode/>
              </torsional>
              <ode/>
            </friction>
          </surface>
        </collision>
        <collision name='hood'>
          <pose frame=''>0 -1.90084 0.676305 0.341247 -0 0</pose>
          <geometry>
            <box>
              <size>1.59797 0.493107 0.265468</size>
            </box>
          </geometry>
          <max_contacts>10</max_contacts>
          <surface>
            <contact>
              <ode/>
            </contact>
            <bounce/>
            <friction>
              <torsional>
                <ode/>
              </torsional>
              <ode/>
            </friction>
          </surface>
        </collision>
        <collision name='windshield'>
          <pose frame=''>0 -0.875105 1.03227 0.335476 -0 0</pose>
          <geometry>
            <box>
              <size>1.16838 1.65425 0.272347</size>
            </box>
          </geometry>
          <max_contacts>10</max_contacts>
          <surface>
            <contact>
              <ode/>
            </contact>
            <bounce/>
            <friction>
              <torsional>
                <ode/>
              </torsional>
              <ode/>
            </friction>
          </surface>
        </collision>
        <collision name='top_front'>
          <pose frame=''>0 0.161236 1.38604 0.13503 -0 0</pose>
          <geometry>
            <box>
              <size>1.27915 0.625988 0.171868</size>
            </box>
          </geometry>
          <max_contacts>10</max_contacts>
          <surface>
            <contact>
              <ode/>
            </contact>
            <bounce/>
            <friction>
              <torsional>
                <ode/>
              </torsional>
              <ode/>
            </friction>
          </surface>
        </collision>
        <collision name='top_rear'>
          <pose frame=''>0 0.817696 1.36007 -0.068997 0 0</pose>
          <geometry>
            <box>
              <size>1.28513 0.771189 0.226557</size>
            </box>
          </geometry>
          <max_contacts>10</max_contacts>
          <surface>
            <contact>
              <ode/>
            </contact>
            <bounce/>
            <friction>
              <torsional>
                <ode/>
              </torsional>
              <ode/>
            </friction>
          </surface>
        </collision>
        <collision name='rear_window'>
          <pose frame=''>0 1.64053 1.17513 -0.262017 0 0</pose>
          <geometry>
            <box>
              <size>1.26785 1.11634 0.244286</size>
            </box>
          </geometry>
          <max_contacts>10</max_contacts>
          <surface>
            <contact>
              <ode/>
            </contact>
            <bounce/>
            <friction>
              <torsional>
                <ode/>
              </torsional>
              <ode/>
            </friction>
          </surface>
        </collision>
        <collision name='trunk'>
          <pose frame=''>0 1.63706 0.88818 0 -0 0</pose>
          <geometry>
            <box>
              <size>1.78806 1.13899 0.482746</size>
            </box>
          </geometry>
          <max_contacts>10</max_contacts>
          <surface>
            <contact>
              <ode/>
            </contact>
            <bounce/>
            <friction>
              <torsional>
                <ode/>
              </torsional>
              <ode/>
            </friction>
          </surface>
        </collision>
        <collision name='back_bumper'>
          <pose frame=''>0 2.05445 0.57787 0 -0 0</pose>
          <geometry>
            <box>
              <size>1.78165 0.512093 0.581427</size>
            </box>
          </geometry>
          <max_contacts>10</max_contacts>
          <surface>
            <contact>
              <ode/>
            </contact>
            <bounce/>
            <friction>
              <torsional>
                <ode/>
              </torsional>
              <ode/>
            </friction>
          </surface>
        </collision>
        <self_collide>0</self_collide>
        <enable_wind>0</enable_wind>
        <kinematic>0</kinematic>
      </link>
      <link name='steering_wheel'>
        <pose frame=''>0.357734 -0.627868 0.988243 -1.3021 0 0</pose>
        <inertial>
          <mass>1</mass>
          <inertia>
            <ixx>0.145833</ixx>
            <ixy>0</ixy>
            <ixz>0</ixz>
            <iyy>0.145833</iyy>
            <iyz>0</iyz>
            <izz>0.125</izz>
          </inertia>
        </inertial>
        <collision name='collision'>
          <geometry>
            <cylinder>
              <radius>0.178172</radius>
              <length>0.041845</length>
            </cylinder>
          </geometry>
          <surface>
            <contact>
              <ode>
                <min_depth>0.003</min_depth>
              </ode>
            </contact>
            <bounce/>
            <friction>
              <torsional>
                <ode/>
              </torsional>
              <ode/>
            </friction>
          </surface>
          <max_contacts>10</max_contacts>
        </collision>
        <visual name='visual'>
          <pose frame=''>0 0 0 1.3021 -0 0</pose>
          <geometry>
            <mesh>
              <uri>model://prius_hybrid/meshes/Hybrid.obj</uri>
              <scale>0.01 0.01 0.01</scale>
              <submesh>
                <name>Steering_Wheel</name>
                <center>1</center>
              </submesh>
            </mesh>
          </geometry>
        </visual>
        <self_collide>0</self_collide>
        <enable_wind>0</enable_wind>
        <kinematic>0</kinematic>
      </link>
      <link name='front_left_wheel'>
        <pose frame=''>0.76 -1.41 0.3 0 -0 0</pose>
        <inertial>
          <mass>11</mass>
          <inertia>
            <ixx>0.586312</ixx>
            <ixy>0</ixy>
            <iyy>0.335529</iyy>
            <ixz>0</ixz>
            <iyz>0</iyz>
            <izz>0.335529</izz>
          </inertia>
        </inertial>
        <visual name='visual'>
          <pose frame=''>0.04 0 0 0 -0 0</pose>
          <geometry>
            <mesh>
              <uri>model://prius_hybrid/meshes/Hybrid.obj</uri>
              <scale>0.01 0.01 0.01</scale>
              <submesh>
                <name>Wheel_Front_Left_</name>
                <center>1</center>
              </submesh>
            </mesh>
          </geometry>
        </visual>
        <collision name='collision'>
          <pose frame=''>0 0 0 3.14159 1.57079 3.14159</pose>
          <geometry>
            <sphere>
              <radius>0.31265</radius>
            </sphere>
          </geometry>
          <surface>
            <friction>
              <ode>
                <mu>0.9</mu>
                <mu2>0.9</mu2>
                <slip1>0</slip1>
                <slip2>0</slip2>
              </ode>
              <torsional>
                <ode/>
              </torsional>
            </friction>
            <contact>
              <ode>
                <min_depth>0.001</min_depth>
                <kp>1e+09</kp>
              </ode>
            </contact>
            <bounce/>
          </surface>
          <max_contacts>10</max_contacts>
        </collision>
        <self_collide>0</self_collide>
        <enable_wind>0</enable_wind>
        <kinematic>0</kinematic>
      </link>
      <link name='front_right_wheel'>
        <pose frame=''>-0.76 -1.41 0.3 0 -0 0</pose>
        <inertial>
          <mass>11</mass>
          <inertia>
            <ixx>0.586312</ixx>
            <ixy>0</ixy>
            <iyy>0.335529</iyy>
            <ixz>0</ixz>
            <iyz>0</iyz>
            <izz>0.335529</izz>
          </inertia>
        </inertial>
        <visual name='visual'>
          <pose frame=''>-0.04 0 0 0 -0 0</pose>
          <pose frame=''>0 0 0 0 -0 0</pose>
          <geometry>
            <mesh>
              <uri>model://prius_hybrid/meshes/Hybrid.obj</uri>
              <scale>0.01 0.01 0.01</scale>
              <submesh>
                <name>Wheel_Front_Right</name>
                <center>1</center>
              </submesh>
            </mesh>
          </geometry>
        </visual>
        <collision name='collision'>
          <pose frame=''>0 0 0 3.14159 1.57079 3.14159</pose>
          <geometry>
            <sphere>
              <radius>0.31265</radius>
            </sphere>
          </geometry>
          <surface>
            <friction>
              <ode>
                <mu>0.9</mu>
                <mu2>0.9</mu2>
                <slip1>0</slip1>
                <slip2>0</slip2>
              </ode>
              <torsional>
                <ode/>
              </torsional>
            </friction>
            <contact>
              <ode>
                <min_depth>0.001</min_depth>
                <kp>1e+09</kp>
              </ode>
            </contact>
            <bounce/>
          </surface>
          <max_contacts>10</max_contacts>
        </collision>
        <self_collide>0</self_collide>
        <enable_wind>0</enable_wind>
        <kinematic>0</kinematic>
      </link>
      <link name='rear_left_wheel'>
        <pose frame=''>0.786 1.45 0.3 0 -0 0</pose>
        <inertial>
          <mass>11</mass>
          <inertia>
            <ixx>0.586312</ixx>
            <ixy>0</ixy>
            <iyy>0.335529</iyy>
            <ixz>0</ixz>
            <iyz>0</iyz>
            <izz>0.335529</izz>
          </inertia>
        </inertial>
        <visual name='visual'>
          <pose frame=''>0.04 0 0 0 -0 0</pose>
          <geometry>
            <mesh>
              <uri>model://prius_hybrid/meshes/Hybrid.obj</uri>
              <scale>0.01 0.01 0.01</scale>
              <submesh>
                <name>Wheel_Front_Left_</name>
                <center>1</center>
              </submesh>
            </mesh>
          </geometry>
        </visual>
        <collision name='collision'>
          <pose frame=''>0 0 0 3.14159 1.57079 3.14159</pose>
          <geometry>
            <sphere>
              <radius>0.31265</radius>
            </sphere>
          </geometry>
          <surface>
            <friction>
              <ode>
                <mu>1.1</mu>
                <mu2>1.1</mu2>
                <slip1>0</slip1>
                <slip2>0</slip2>
              </ode>
              <torsional>
                <ode/>
              </torsional>
            </friction>
            <contact>
              <ode>
                <min_depth>0.001</min_depth>
                <kp>1e+09</kp>
              </ode>
            </contact>
            <bounce/>
          </surface>
          <max_contacts>10</max_contacts>
        </collision>
        <self_collide>0</self_collide>
        <enable_wind>0</enable_wind>
        <kinematic>0</kinematic>
      </link>
      <link name='rear_right_wheel'>
        <pose frame=''>-0.786 1.45 0.3 0 -0 0</pose>
        <inertial>
          <mass>11</mass>
          <inertia>
            <ixx>0.586312</ixx>
            <ixy>0</ixy>
            <iyy>0.335529</iyy>
            <ixz>0</ixz>
            <iyz>0</iyz>
            <izz>0.335529</izz>
          </inertia>
        </inertial>
        <visual name='visual'>
          <pose frame=''>-0.04 0 0 0 -0 0</pose>
          <geometry>
            <mesh>
              <uri>model://prius_hybrid/meshes/Hybrid.obj</uri>
              <scale>0.01 0.01 0.01</scale>
              <submesh>
                <name>Wheel_Front_Right</name>
                <center>1</center>
              </submesh>
            </mesh>
          </geometry>
        </visual>
        <collision name='collision'>
          <pose frame=''>0 0 0 3.14159 1.57079 3.14159</pose>
          <geometry>
            <sphere>
              <radius>0.31265</radius>
            </sphere>
          </geometry>
          <surface>
            <friction>
              <ode>
                <mu>1.1</mu>
                <mu2>1.1</mu2>
                <slip1>0</slip1>
                <slip2>0</slip2>
              </ode>
              <torsional>
                <ode/>
              </torsional>
            </friction>
            <contact>
              <ode>
                <min_depth>0.001</min_depth>
                <kp>1e+09</kp>
              </ode>
            </contact>
            <bounce/>
          </surface>
          <max_contacts>10</max_contacts>
        </collision>
        <self_collide>0</self_collide>
        <enable_wind>0</enable_wind>
        <kinematic>0</kinematic>
      </link>
      <joint name='front_left_combined_joint' type='universal'>
        <pose frame=''>0 0 0 -0.087266 0 0</pose>
        <child>front_left_wheel</child>
        <parent>chassis</parent>
        <axis>
          <xyz>0 0 1</xyz>
          <limit>
            <lower>-0.8727</lower>
            <upper>0.8727</upper>
          </limit>
          <use_parent_model_frame>0</use_parent_model_frame>
          <dynamics>
            <spring_reference>0</spring_reference>
            <spring_stiffness>0</spring_stiffness>
          </dynamics>
        </axis>
        <axis2>
          <xyz>1 0 0</xyz>
          <dynamics>
            <friction>18.0474</friction>
            <spring_reference>0</spring_reference>
            <spring_stiffness>0</spring_stiffness>
          </dynamics>
          <use_parent_model_frame>0</use_parent_model_frame>
        </axis2>
      </joint>
      <joint name='front_right_combined_joint' type='universal'>
        <pose frame=''>0 0 0 -0.087266 0 0</pose>
        <child>front_right_wheel</child>
        <parent>chassis</parent>
        <axis>
          <xyz>0 0 1</xyz>
          <limit>
            <lower>-0.8727</lower>
            <upper>0.8727</upper>
          </limit>
          <use_parent_model_frame>0</use_parent_model_frame>
          <dynamics>
            <spring_reference>0</spring_reference>
            <spring_stiffness>0</spring_stiffness>
          </dynamics>
        </axis>
        <axis2>
          <xyz>1 0 0</xyz>
          <dynamics>
            <friction>18.0474</friction>
            <spring_reference>0</spring_reference>
            <spring_stiffness>0</spring_stiffness>
          </dynamics>
          <use_parent_model_frame>0</use_parent_model_frame>
        </axis2>
      </joint>
      <link name='rear_axle'>
        <pose frame=''>0 1.45 0.3 0 -0 0</pose>
        <inertial>
          <mass>30</mass>
          <inertia>
            <ixx>0.084375</ixx>
            <ixy>0</ixy>
            <iyy>4.64581</iyy>
            <ixz>0</ixz>
            <iyz>0</iyz>
            <izz>4.64581</izz>
          </inertia>
        </inertial>
        <visual name='visual'>
          <pose frame=''>0 0 0 3.14159 1.57079 3.14159</pose>
          <geometry>
            <cylinder>
              <length>1.357</length>
              <radius>0.075</radius>
            </cylinder>
          </geometry>
          <material>
            <script>
              <name>Gazebo/Grey</name>
              <uri>file://media/materials/scripts/gazebo.material</uri>
            </script>
          </material>
        </visual>
        <self_collide>0</self_collide>
        <enable_wind>0</enable_wind>
        <kinematic>0</kinematic>
      </link>
      <joint name='rear_axle_joint' type='revolute'>
        <child>rear_axle</child>
        <parent>chassis</parent>
        <axis>
          <xyz>0 1 0</xyz>
          <limit>
            <lower>-0.0508906</lower>
            <upper>0.0508906</upper>
          </limit>
          <dynamics>
            <spring_stiffness>20000</spring_stiffness>
            <damping>2000</damping>
            <spring_reference>0</spring_reference>
          </dynamics>
          <use_parent_model_frame>0</use_parent_model_frame>
        </axis>
      </joint>
      <joint name='rear_left_wheel_joint' type='revolute'>
        <child>rear_left_wheel</child>
        <parent>rear_axle</parent>
        <axis>
          <xyz>1 0 0</xyz>
          <dynamics>
            <friction>12.0316</friction>
            <spring_reference>0</spring_reference>
            <spring_stiffness>0</spring_stiffness>
          </dynamics>
          <use_parent_model_frame>0</use_parent_model_frame>
          <limit>
            <lower>-1e+16</lower>
            <upper>1e+16</upper>
          </limit>
        </axis>
      </joint>
      <joint name='rear_right_wheel_joint' type='revolute'>
        <child>rear_right_wheel</child>
        <parent>rear_axle</parent>
        <axis>
          <xyz>1 0 0</xyz>
          <dynamics>
            <friction>12.0316</friction>
            <spring_reference>0</spring_reference>
            <spring_stiffness>0</spring_stiffness>
          </dynamics>
          <use_parent_model_frame>0</use_parent_model_frame>
          <limit>
            <lower>-1e+16</lower>
            <upper>1e+16</upper>
          </limit>
        </axis>
      </joint>
      <joint name='steering_joint' type='revolute'>
        <pose frame=''>-0.002 0 0 0 -0 0</pose>
        <parent>chassis</parent>
        <child>steering_wheel</child>
        <axis>
          <xyz>0 0.964095 0.265556</xyz>
          <limit>
            <lower>-7.85</lower>
            <upper>7.85</upper>
          </limit>
          <dynamics>
            <damping>1</damping>
            <spring_reference>0</spring_reference>
            <spring_stiffness>0</spring_stiffness>
          </dynamics>
          <use_parent_model_frame>1</use_parent_model_frame>
        </axis>
        <physics>
          <ode>
            <cfm_damping>1</cfm_damping>
            <limit>
              <cfm>0</cfm>
              <erp>0.2</erp>
            </limit>
          </ode>
        </physics>
      </joint>
    </model>
  </world>
</sdf>
